Workbook
Name L_business_model: Lookups!$A$2:$A$6
Name L_site_status: Lookups!$B$2:$B$5
Name L_tier: Lookups!$C$2:$C$4
Name L_site_category: Lookups!$D$2:$D$4
Name L_redundancy: Lookups!$E$2:$E$4
Name L_room_type: Lookups!$F$2:$F$9
Name L_containment: Lookups!$G$2:$G$4
Name L_cooling_method: Lookups!$H$2:$H$4
Name L_rack_role: Lookups!$I$2:$I$10
Name L_owner: Lookups!$J$2:$J$3
Name L_density: Lookups!$K$2:$K$3
Name L_yes_no: Lookups!$L$2:$L$3
Name L_feed_type: Lookups!$M$2:$M$3
Name L_feed_role: Lookups!$N$2:$N$3
Name L_plant_kind: Lookups!$O$2:$O$3
Name L_test_result: Lookups!$P$2:$P$3
Name L_cooling_type: Lookups!$Q$2:$Q$4
Name L_sensor_kind: Lookups!$R$2:$R$4
Name L_device_role: Lookups!$S$2:$S$10
Name L_layer: Lookups!$T$2:$T$5
Name L_lifecycle: Lookups!$U$2:$U$5
Name L_if_admin: Lookups!$V$2:$V$4
Name L_link_role: Lookups!$W$2:$W$6
Name L_protocol: Lookups!$X$2:$X$6
Name L_gpu_model: Lookups!$Y$2:$Y$9
Name L_gpu_vendor: Lookups!$Z$2:$Z$3
Name L_scheduler: Lookups!$AA$2:$AA$3
Name L_air_liquid: Lookups!$AB$2:$AB$3
Name L_service_type: Lookups!$AC$2:$AC$24
Name L_service_unit: Lookups!$AD$2:$AD$9
Name L_collector_protocol: Lookups!$AE$2:$AE$8
Name L_collector_domain: Lookups!$AF$2:$AF$5
Name L_pdu_side: Lookups!$AG$2:$AG$3
Name L_pdu_kind: Lookups!$AH$2:$AH$3
Name L_panel_kind: Lookups!$AI$2:$AI$4
Name L_panel_role: Lookups!$AJ$2:$AJ$3
Name L_link_end: Lookups!$AK$2:$AK$3
Name L_tray_route: Lookups!$AL$2:$AL$3
Name L_detection: Lookups!$AM$2:$AM$3
Name L_suppression: Lookups!$AN$2:$AN$4
Name L_release_mode: Lookups!$AO$2:$AO$4
Name L_door_kind: Lookups!$AP$2:$AP$6
Name L_reader: Lookups!$AQ$2:$AQ$4
Name L_support_level: Lookups!$AR$2:$AR$5
Name L_pm_kind: Lookups!$AS$2:$AS$8
Name L_oncall_role: Lookups!$AT$2:$AT$7

Sheet README
A1: SynapseDC · Sample data for two datacenters · Colocation · India · MH-DC-001, MH-DC-002
A2: A complete, end-to-end export of MH-DC-001, MH-DC-002 as the platform holds them (data clock 2026-10-01 07:50 UTC): the two sites, their floors, rooms, racks, power and cooling plant, every device with its ports, the cables between them, GPU clusters, the customers served there and their services, plus the physical, safety, lifecycle and maintenance records. Only links whose two ends are in these sites and only customers who buy something there are included. Use it as the worked example for the import template: every sheet is filled exactly the way the customer should fill it for their own datacenters, the Summary sheet shows what the platform will then display. Snapshot_* sheets keep the alarms, incidents and changes of that moment for the record; they are not imported.
A3: Version 1.0 · 12-Oct-2026 · matches the DCO data model (app/src/api/types.ts)
A5: What this workbook is for
A6: Use it to collect everything the DCO platform needs to know about a customer's datacenters BEFORE monitoring is switched on: sites, floors, rooms, racks, power and cooling plant, sensors, every racked device, its ports and cables, GPU clusters, customers and the services they buy, and the monitoring sources.
A8: How to fill it
A9: 1. Fill the sheets in tab order. A sheet can only point at IDs that exist in the sheets before it (Sites → Floors → Rooms → Racks → … → Services).
A10: 2. Row 1 holds the import keys. Don't rename, reorder or delete columns. Hover over a header for its meaning; the Field_Dictionary sheet lists every field.
A11: 3. Header colours: dark blue = required · amber = required in some cases (see the note) · grey = optional · green = calculated by a formula (don't type it).
A12: 4. Columns with a fixed set of values have a dropdown (from the Lookups sheet). Dates use YYYY-MM-DD. Numbers are plain, with no units in the cell. Lists inside a cell use ";".
A13: 5. IDs must be unique and stable: the system keys every alarm, incident and revenue figure on them. Recommended: site XX-DC-NNN, then <site>-<object> (MP-DC-001-A01).
A14: 6. Check the Summary sheet when you finish. Every count must match what the customer expects, and the checks column must say OK.
... A24: Sheet order and the system object each one fills
A25: Sheet | B25: System object | C25: What goes in it | D25: Example rows
A26: Sites | B26: Datacenter + Location | C26: One row per datacenter. | D26: 2
A27: Floors | B27: Datacenter.floors[] | C27: One row per floor. | D27: 4
A28: Rooms | B28: Datacenter.floors[].rooms[] | C28: One row per room / hall. | D28: 8
A29: Racks | B29: Rack | C29: One row per cabinet, including tenant cabinets and AI cages. | D29: 32
A30: Power_Feeds | B30: Datacenter.power.feeds[] (PowerFeed) | C30: Utility, DG and DC-plant feeds. | D30: 6
A31: UPS | B31: Datacenter.power.ups[] (UpsUnit) | C31: One row per UPS module or system. | D31: 8
A32: Generators | B32: Datacenter.power.dg | C32: Diesel generator sets. | D32: 2
A33: DC_Plant | B33: Datacenter.power.battery + rectifier | C33: 48 V DC plant: rectifiers and battery banks. | D33: 4
A34: Cooling_Units | B34: Datacenter.cooling.units[] (CoolingUnit) | C34: CRAH, CRAC and CDU units. | D34: 17
A35: CDUs | B35: Cdu | C35: Liquid-cooling loops (only for liquid-cooled racks). | D35: 1
A36: Sensors | B36: Datacenter.cooling.sensors[] (EnvSensor) | C36: Environment sensors. | D36: 8
A37: Devices | B37: NetworkElement | C37: Every racked device: network, servers, storage, GPU nodes, and opaque tenant gear blocks. | D37: 183
... A66: Snapshot_Orders | B66: CrossConnectOrder + RemoteHandsTicket (snapshot) | C66: Colocation cross-connect orders and remote-hands tickets. | D66: 41
A67: Summary | B67: — | C67: Counts per site and the reconciliation checks (formulas).
A68: Field_Dictionary | B68: — | C68: Every column: required, type, allowed values, the system field it maps to.
A69: Lookups | B69: — | C69: Allowed values behind the dropdowns.

Sheet Summary
A1: Summary and reconciliation checks
A2: Every figure is a formula over the data sheets. Check it with the customer: these are the numbers the platform will show.
A4: Measure | B4: =IF('Sites'!A2="","(site 1)",'Sites'!A2) | C4: =IF('Sites'!A3="","(site 2)",'Sites'!A3) | D4: =IF('Sites'!A4="","(site 3)",'Sites'!A4) | E4: =IF('Sites'!A5="","(site 4)",'Sites'!A5) | F4: =IF('Sites'!A6="","(site 5)",'Sites'!A6) | G4: =IF('Sites'!A7="","(site 6)",'Sites'!A7) | H4: Total
A5: Floors | B5: =IF('Sites'!$A$2="","",COUNTIF('Floors'!$A$2:$A$2000,B$4)) | C5: =IF('Sites'!$A$3="","",COUNTIF('Floors'!$A$2:$A$2000,C$4)) | D5: =IF('Sites'!$A$4="","",COUNTIF('Floors'!$A$2:$A$2000,D$4)) | E5: =IF('Sites'!$A$5="","",COUNTIF('Floors'!$A$2:$A$2000,E$4)) | F5: =IF('Sites'!$A$6="","",COUNTIF('Floors'!$A$2:$A$2000,F$4)) | G5: =IF('Sites'!$A$7="","",COUNTIF('Floors'!$A$2:$A$2000,G$4)) | H5: =SUM(B5:G5)
A6: Rooms | B6: =IF('Sites'!$A$2="","",COUNTIF('Rooms'!$A$2:$A$2000,B$4)) | C6: =IF('Sites'!$A$3="","",COUNTIF('Rooms'!$A$2:$A$2000,C$4)) | D6: =IF('Sites'!$A$4="","",COUNTIF('Rooms'!$A$2:$A$2000,D$4)) | E6: =IF('Sites'!$A$5="","",COUNTIF('Rooms'!$A$2:$A$2000,E$4)) | F6: =IF('Sites'!$A$6="","",COUNTIF('Rooms'!$A$2:$A$2000,F$4)) | G6: =IF('Sites'!$A$7="","",COUNTIF('Rooms'!$A$2:$A$2000,G$4)) | H6: =SUM(B6:G6)
A7: Racks | B7: =IF('Sites'!$A$2="","",COUNTIF('Racks'!$B$2:$B$2000,B$4)) | C7: =IF('Sites'!$A$3="","",COUNTIF('Racks'!$B$2:$B$2000,C$4)) | D7: =IF('Sites'!$A$4="","",COUNTIF('Racks'!$B$2:$B$2000,D$4)) | E7: =IF('Sites'!$A$5="","",COUNTIF('Racks'!$B$2:$B$2000,E$4)) | F7: =IF('Sites'!$A$6="","",COUNTIF('Racks'!$B$2:$B$2000,F$4)) | G7: =IF('Sites'!$A$7="","",COUNTIF('Racks'!$B$2:$B$2000,G$4)) | H7: =SUM(B7:G7)
A8: of which tenant cabinets | B8: =IF('Sites'!$A$2="","",COUNTIFS('Racks'!$B$2:$B$2000,B$4,'Racks'!$J$2:$J$2000,"tenant")) | C8: =IF('Sites'!$A$3="","",COUNTIFS('Racks'!$B$2:$B$2000,C$4,'Racks'!$J$2:$J$2000,"tenant")) | D8: =IF('Sites'!$A$4="","",COUNTIFS('Racks'!$B$2:$B$2000,D$4,'Racks'!$J$2:$J$2000,"tenant")) | E8: =IF('Sites'!$A$5="","",COUNTIFS('Racks'!$B$2:$B$2000,E$4,'Racks'!$J$2:$J$2000,"tenant")) | F8: =IF('Sites'!$A$6="","",COUNTIFS('Racks'!$B$2:$B$2000,F$4,'Racks'!$J$2:$J$2000,"tenant")) | G8: =IF('Sites'!$A$7="","",COUNTIFS('Racks'!$B$2:$B$2000,G$4,'Racks'!$J$2:$J$2000,"tenant")) | H8: =SUM(B8:G8)
A9: of which AI / high-density | B9: =IF('Sites'!$A$2="","",COUNTIFS('Racks'!$B$2:$B$2000,B$4,'Racks'!$M$2:$M$2000,"ai")) | C9: =IF('Sites'!$A$3="","",COUNTIFS('Racks'!$B$2:$B$2000,C$4,'Racks'!$M$2:$M$2000,"ai")) | D9: =IF('Sites'!$A$4="","",COUNTIFS('Racks'!$B$2:$B$2000,D$4,'Racks'!$M$2:$M$2000,"ai")) | E9: =IF('Sites'!$A$5="","",COUNTIFS('Racks'!$B$2:$B$2000,E$4,'Racks'!$M$2:$M$2000,"ai")) | F9: =IF('Sites'!$A$6="","",COUNTIFS('Racks'!$B$2:$B$2000,F$4,'Racks'!$M$2:$M$2000,"ai")) | G9: =IF('Sites'!$A$7="","",COUNTIFS('Racks'!$B$2:$B$2000,G$4,'Racks'!$M$2:$M$2000,"ai")) | H9: =SUM(B9:G9)
A10: Rack power budget (kW) | B10: =IF('Sites'!$A$2="","",SUMIF('Racks'!$B$2:$B$2000,B$4,'Racks'!$I$2:$I$2000)) | C10: =IF('Sites'!$A$3="","",SUMIF('Racks'!$B$2:$B$2000,C$4,'Racks'!$I$2:$I$2000)) | D10: =IF('Sites'!$A$4="","",SUMIF('Racks'!$B$2:$B$2000,D$4,'Racks'!$I$2:$I$2000)) | E10: =IF('Sites'!$A$5="","",SUMIF('Racks'!$B$2:$B$2000,E$4,'Racks'!$I$2:$I$2000)) | F10: =IF('Sites'!$A$6="","",SUMIF('Racks'!$B$2:$B$2000,F$4,'Racks'!$I$2:$I$2000)) | G10: =IF('Sites'!$A$7="","",SUMIF('Racks'!$B$2:$B$2000,G$4,'Racks'!$I$2:$I$2000)) | H10: =SUM(B10:G10)
A11: Site IT capacity (kW) | B11: =IF('Sites'!$A$2="","",SUMIF('Sites'!$A$2:$A$2000,B$4,'Sites'!$O$2:$O$2000)) | C11: =IF('Sites'!$A$3="","",SUMIF('Sites'!$A$2:$A$2000,C$4,'Sites'!$O$2:$O$2000)) | D11: =IF('Sites'!$A$4="","",SUMIF('Sites'!$A$2:$A$2000,D$4,'Sites'!$O$2:$O$2000)) | E11: =IF('Sites'!$A$5="","",SUMIF('Sites'!$A$2:$A$2000,E$4,'Sites'!$O$2:$O$2000)) | F11: =IF('Sites'!$A$6="","",SUMIF('Sites'!$A$2:$A$2000,F$4,'Sites'!$O$2:$O$2000)) | G11: =IF('Sites'!$A$7="","",SUMIF('Sites'!$A$2:$A$2000,G$4,'Sites'!$O$2:$O$2000)) | H11: =SUM(B11:G11)
A12: Devices (all) | B12: =IF('Sites'!$A$2="","",COUNTIFS('Devices'!$B$2:$B$2000,B$4)) | C12: =IF('Sites'!$A$3="","",COUNTIFS('Devices'!$B$2:$B$2000,C$4)) | D12: =IF('Sites'!$A$4="","",COUNTIFS('Devices'!$B$2:$B$2000,D$4)) | E12: =IF('Sites'!$A$5="","",COUNTIFS('Devices'!$B$2:$B$2000,E$4)) | F12: =IF('Sites'!$A$6="","",COUNTIFS('Devices'!$B$2:$B$2000,F$4)) | G12: =IF('Sites'!$A$7="","",COUNTIFS('Devices'!$B$2:$B$2000,G$4)) | H12: =SUM(B12:G12)
A13: operator devices | B13: =IF('Sites'!$A$2="","",COUNTIFS('Devices'!$B$2:$B$2000,B$4,'Devices'!$P$2:$P$2000,"operator")) | C13: =IF('Sites'!$A$3="","",COUNTIFS('Devices'!$B$2:$B$2000,C$4,'Devices'!$P$2:$P$2000,"operator")) | D13: =IF('Sites'!$A$4="","",COUNTIFS('Devices'!$B$2:$B$2000,D$4,'Devices'!$P$2:$P$2000,"operator")) | E13: =IF('Sites'!$A$5="","",COUNTIFS('Devices'!$B$2:$B$2000,E$4,'Devices'!$P$2:$P$2000,"operator")) | F13: =IF('Sites'!$A$6="","",COUNTIFS('Devices'!$B$2:$B$2000,F$4,'Devices'!$P$2:$P$2000,"operator")) | G13: =IF('Sites'!$A$7="","",COUNTIFS('Devices'!$B$2:$B$2000,G$4,'Devices'!$P$2:$P$2000,"operator")) | H13: =SUM(B13:G13)
A14: tenant gear blocks | B14: =IF('Sites'!$A$2="","",COUNTIFS('Devices'!$B$2:$B$2000,B$4,'Devices'!$P$2:$P$2000,"tenant")) | C14: =IF('Sites'!$A$3="","",COUNTIFS('Devices'!$B$2:$B$2000,C$4,'Devices'!$P$2:$P$2000,"tenant")) | D14: =IF('Sites'!$A$4="","",COUNTIFS('Devices'!$B$2:$B$2000,D$4,'Devices'!$P$2:$P$2000,"tenant")) | E14: =IF('Sites'!$A$5="","",COUNTIFS('Devices'!$B$2:$B$2000,E$4,'Devices'!$P$2:$P$2000,"tenant")) | F14: =IF('Sites'!$A$6="","",COUNTIFS('Devices'!$B$2:$B$2000,F$4,'Devices'!$P$2:$P$2000,"tenant")) | G14: =IF('Sites'!$A$7="","",COUNTIFS('Devices'!$B$2:$B$2000,G$4,'Devices'!$P$2:$P$2000,"tenant")) | H14: =SUM(B14:G14)
A15: GPU nodes | B15: =IF('Sites'!$A$2="","",COUNTIFS('Devices'!$B$2:$B$2000,B$4,'Devices'!$D$2:$D$2000,"GPU")) | C15: =IF('Sites'!$A$3="","",COUNTIFS('Devices'!$B$2:$B$2000,C$4,'Devices'!$D$2:$D$2000,"GPU")) | D15: =IF('Sites'!$A$4="","",COUNTIFS('Devices'!$B$2:$B$2000,D$4,'Devices'!$D$2:$D$2000,"GPU")) | E15: =IF('Sites'!$A$5="","",COUNTIFS('Devices'!$B$2:$B$2000,E$4,'Devices'!$D$2:$D$2000,"GPU")) | F15: =IF('Sites'!$A$6="","",COUNTIFS('Devices'!$B$2:$B$2000,F$4,'Devices'!$D$2:$D$2000,"GPU")) | G15: =IF('Sites'!$A$7="","",COUNTIFS('Devices'!$B$2:$B$2000,G$4,'Devices'!$D$2:$D$2000,"GPU")) | H15: =SUM(B15:G15)
A16: network (routers, firewalls, switches) | B16: =IF('Sites'!$A$2="","",COUNTIFS('Devices'!$B$2:$B$2000,B$4,'Devices'!$D$2:$D$2000,"Router")+COUNTIFS('Devices'!$B$2:$B$2000,B$4,'Devices'!$D$2:$D$2000,"Firewall")+COUNTIFS('Devices'!$B$2:$B$2000,B$4,'Devices'!$D$2:$D$2000,"Switch")) | C16: =IF('Sites'!$A$3="","",COUNTIFS('Devices'!$B$2:$B$2000,C$4,'Devices'!$D$2:$D$2000,"Router")+COUNTIFS('Devices'!$B$2:$B$2000,C$4,'Devices'!$D$2:$D$2000,"Firewall")+COUNTIFS('Devices'!$B$2:$B$2000,C$4,'Devices'!$D$2:$D$2000,"Switch")) | D16: =IF('Sites'!$A$4="","",COUNTIFS('Devices'!$B$2:$B$2000,D$4,'Devices'!$D$2:$D$2000,"Router")+COUNTIFS('Devices'!$B$2:$B$2000,D$4,'Devices'!$D$2:$D$2000,"Firewall")+COUNTIFS('Devices'!$B$2:$B$2000,D$4,'Devices'!$D$2:$D$2000,"Switch")) | E16: =IF('Sites'!$A$5="","",COUNTIFS('Devices'!$B$2:$B$2000,E$4,'Devices'!$D$2:$D$2000,"Router")+COUNTIFS('Devices'!$B$2:$B$2000,E$4,'Devices'!$D$2:$D$2000,"Firewall")+COUNTIFS('Devices'!$B$2:$B$2000,E$4,'Devices'!$D$2:$D$2000,"Switch")) | F16: =IF('Sites'!$A$6="","",COUNTIFS('Devices'!$B$2:$B$2000,F$4,'Devices'!$D$2:$D$2000,"Router")+COUNTIFS('Devices'!$B$2:$B$2000,F$4,'Devices'!$D$2:$D$2000,"Firewall")+COUNTIFS('Devices'!$B$2:$B$2000,F$4,'Devices'!$D$2:$D$2000,"Switch")) | G16: =IF('Sites'!$A$7="","",COUNTIFS('Devices'!$B$2:$B$2000,G$4,'Devices'!$D$2:$D$2000,"Router")+COUNTIFS('Devices'!$B$2:$B$2000,G$4,'Devices'!$D$2:$D$2000,"Firewall")+COUNTIFS('Devices'!$B$2:$B$2000,G$4,'Devices'!$D$2:$D$2000,"Switch")) | H16: =SUM(B16:G16)
A17: UPS units | B17: =IF('Sites'!$A$2="","",COUNTIF('UPS'!$B$2:$B$2000,B$4)) | C17: =IF('Sites'!$A$3="","",COUNTIF('UPS'!$B$2:$B$2000,C$4)) | D17: =IF('Sites'!$A$4="","",COUNTIF('UPS'!$B$2:$B$2000,D$4)) | E17: =IF('Sites'!$A$5="","",COUNTIF('UPS'!$B$2:$B$2000,E$4)) | F17: =IF('Sites'!$A$6="","",COUNTIF('UPS'!$B$2:$B$2000,F$4)) | G17: =IF('Sites'!$A$7="","",COUNTIF('UPS'!$B$2:$B$2000,G$4)) | H17: =SUM(B17:G17)
A18: UPS capacity (kW) | B18: =IF('Sites'!$A$2="","",SUMIF('UPS'!$B$2:$B$2000,B$4,'UPS'!$H$2:$H$2000)) | C18: =IF('Sites'!$A$3="","",SUMIF('UPS'!$B$2:$B$2000,C$4,'UPS'!$H$2:$H$2000)) | D18: =IF('Sites'!$A$4="","",SUMIF('UPS'!$B$2:$B$2000,D$4,'UPS'!$H$2:$H$2000)) | E18: =IF('Sites'!$A$5="","",SUMIF('UPS'!$B$2:$B$2000,E$4,'UPS'!$H$2:$H$2000)) | F18: =IF('Sites'!$A$6="","",SUMIF('UPS'!$B$2:$B$2000,F$4,'UPS'!$H$2:$H$2000)) | G18: =IF('Sites'!$A$7="","",SUMIF('UPS'!$B$2:$B$2000,G$4,'UPS'!$H$2:$H$2000)) | H18: =SUM(B18:G18)
A19: Generators | B19: =IF('Sites'!$A$2="","",COUNTIF('Generators'!$B$2:$B$2000,B$4)) | C19: =IF('Sites'!$A$3="","",COUNTIF('Generators'!$B$2:$B$2000,C$4)) | D19: =IF('Sites'!$A$4="","",COUNTIF('Generators'!$B$2:$B$2000,D$4)) | E19: =IF('Sites'!$A$5="","",COUNTIF('Generators'!$B$2:$B$2000,E$4)) | F19: =IF('Sites'!$A$6="","",COUNTIF('Generators'!$B$2:$B$2000,F$4)) | G19: =IF('Sites'!$A$7="","",COUNTIF('Generators'!$B$2:$B$2000,G$4)) | H19: =SUM(B19:G19)
A20: Cooling units | B20: =IF('Sites'!$A$2="","",COUNTIF('Cooling_Units'!$B$2:$B$2000,B$4)) | C20: =IF('Sites'!$A$3="","",COUNTIF('Cooling_Units'!$B$2:$B$2000,C$4)) | D20: =IF('Sites'!$A$4="","",COUNTIF('Cooling_Units'!$B$2:$B$2000,D$4)) | E20: =IF('Sites'!$A$5="","",COUNTIF('Cooling_Units'!$B$2:$B$2000,E$4)) | F20: =IF('Sites'!$A$6="","",COUNTIF('Cooling_Units'!$B$2:$B$2000,F$4)) | G20: =IF('Sites'!$A$7="","",COUNTIF('Cooling_Units'!$B$2:$B$2000,G$4)) | H20: =SUM(B20:G20)
A21: Cooling unit capacity (kW) | B21: =IF('Sites'!$A$2="","",SUMIF('Cooling_Units'!$B$2:$B$2000,B$4,'Cooling_Units'!$H$2:$H$2000)) | C21: =IF('Sites'!$A$3="","",SUMIF('Cooling_Units'!$B$2:$B$2000,C$4,'Cooling_Units'!$H$2:$H$2000)) | D21: =IF('Sites'!$A$4="","",SUMIF('Cooling_Units'!$B$2:$B$2000,D$4,'Cooling_Units'!$H$2:$H$2000)) | E21: =IF('Sites'!$A$5="","",SUMIF('Cooling_Units'!$B$2:$B$2000,E$4,'Cooling_Units'!$H$2:$H$2000)) | F21: =IF('Sites'!$A$6="","",SUMIF('Cooling_Units'!$B$2:$B$2000,F$4,'Cooling_Units'!$H$2:$H$2000)) | G21: =IF('Sites'!$A$7="","",SUMIF('Cooling_Units'!$B$2:$B$2000,G$4,'Cooling_Units'!$H$2:$H$2000)) | H21: =SUM(B21:G21)
A22: Sensors | B22: =IF('Sites'!$A$2="","",COUNTIF('Sensors'!$B$2:$B$2000,B$4)) | C22: =IF('Sites'!$A$3="","",COUNTIF('Sensors'!$B$2:$B$2000,C$4)) | D22: =IF('Sites'!$A$4="","",COUNTIF('Sensors'!$B$2:$B$2000,D$4)) | E22: =IF('Sites'!$A$5="","",COUNTIF('Sensors'!$B$2:$B$2000,E$4)) | F22: =IF('Sites'!$A$6="","",COUNTIF('Sensors'!$B$2:$B$2000,F$4)) | G22: =IF('Sites'!$A$7="","",COUNTIF('Sensors'!$B$2:$B$2000,G$4)) | H22: =SUM(B22:G22)
A23: Collectors | B23: =IF('Sites'!$A$2="","",COUNTIF('Collectors'!$B$2:$B$2000,B$4)) | C23: =IF('Sites'!$A$3="","",COUNTIF('Collectors'!$B$2:$B$2000,C$4)) | D23: =IF('Sites'!$A$4="","",COUNTIF('Collectors'!$B$2:$B$2000,D$4)) | E23: =IF('Sites'!$A$5="","",COUNTIF('Collectors'!$B$2:$B$2000,E$4)) | F23: =IF('Sites'!$A$6="","",COUNTIF('Collectors'!$B$2:$B$2000,F$4)) | G23: =IF('Sites'!$A$7="","",COUNTIF('Collectors'!$B$2:$B$2000,G$4)) | H23: =SUM(B23:G23)
A24: Services | B24: =IF('Sites'!$A$2="","",COUNTIF('Services'!$D$2:$D$2000,B$4)) | C24: =IF('Sites'!$A$3="","",COUNTIF('Services'!$D$2:$D$2000,C$4)) | D24: =IF('Sites'!$A$4="","",COUNTIF('Services'!$D$2:$D$2000,D$4)) | E24: =IF('Sites'!$A$5="","",COUNTIF('Services'!$D$2:$D$2000,E$4)) | F24: =IF('Sites'!$A$6="","",COUNTIF('Services'!$D$2:$D$2000,F$4)) | G24: =IF('Sites'!$A$7="","",COUNTIF('Services'!$D$2:$D$2000,G$4)) | H24: =SUM(B24:G24)
A25: Services monthly revenue (₹) | B25: =IF('Sites'!$A$2="","",SUMIF('Services'!$D$2:$D$2000,B$4,'Services'!$M$2:$M$2000)) | C25: =IF('Sites'!$A$3="","",SUMIF('Services'!$D$2:$D$2000,C$4,'Services'!$M$2:$M$2000)) | D25: =IF('Sites'!$A$4="","",SUMIF('Services'!$D$2:$D$2000,D$4,'Services'!$M$2:$M$2000)) | E25: =IF('Sites'!$A$5="","",SUMIF('Services'!$D$2:$D$2000,E$4,'Services'!$M$2:$M$2000)) | F25: =IF('Sites'!$A$6="","",SUMIF('Services'!$D$2:$D$2000,F$4,'Services'!$M$2:$M$2000)) | G25: =IF('Sites'!$A$7="","",SUMIF('Services'!$D$2:$D$2000,G$4,'Services'!$M$2:$M$2000)) | H25: =SUM(B25:G25)
A28: Checks
A29: Check | B29: Result | C29: Why it matters
A30: Every device sits in a rack that exists | B30: =IF(SUMPRODUCT(--(COUNTIF('Racks'!$A$2:$A$2000,'Devices'!$L$2:$L$184)=0))=0,"OK","FIX: unknown rack_id") | C30: The twin and rack views place devices by rack_id.
A31: No rack is over-filled (used U ≤ height U) | B31: =IF(SUMPRODUCT(--('Racks'!$R$2:$R$33>'Racks'!$H$2:$H$33))=0,"OK","FIX: rack over capacity") | C31: used_u is calculated from Devices.
A32: Device IDs are unique | B32: =IF(SUMPRODUCT(--(COUNTIF('Devices'!$A$2:$A$184,'Devices'!$A$2:$A$184)>1))=0,"OK","FIX: duplicate device_id") | C32: Alarms and incidents key on the device ID.
A33: Operator serial numbers are unique | B33: =IF(SUMPRODUCT(('Devices'!$I$2:$I$184<>"")*(COUNTIF('Devices'!$I$2:$I$184,'Devices'!$I$2:$I$184)>1))=0,"OK","FIX: duplicate serial") | C33: Discovery matches the polled serial against this one.
A34: Tenant racks name a tenant and contracted kW | B34: =IF(COUNTIFS('Racks'!$J$2:$J$33,"tenant",'Racks'!$K$2:$K$33,"")+COUNTIFS('Racks'!$J$2:$J$33,"tenant",'Racks'!$L$2:$L$33,"")=0,"OK","FIX: tenant rack missing data") | C34: Colocation power-over-contract is measured against it.
A35: Liquid racks name a CDU | B35: =IF(COUNTIFS('Racks'!$N$2:$N$33,"Y",'Racks'!$O$2:$O$33,"")=0,"OK","FIX: liquid rack without CDU") | C35: A CDU fault is traced to the racks it feeds.
A36: Rack budget fits site IT capacity | B36: =IF(SUMPRODUCT(--(B10:G10>B11:G11))=0,"OK","CHECK: racks exceed IT capacity") | C36: Power and space views compare the two.
A37: GPU nodes = GPU devices in service | B37: =IF(COUNTA('GPU_Nodes'!$A$2:$A$2000)=COUNTIFS('Devices'!$D$2:$D$2000,"GPU",'Devices'!$R$2:$R$2000,"Y"),"OK","FIX: GPU_Nodes and Devices differ") | C37: Each GPU node in service needs a rack position and a telemetry record; hosts not yet commissioned into a cluster have none.
A38: Every installed device has a power connection | B38: =IF(SUMPRODUCT(('Devices'!$O$2:$O$184<>"Planned")*('Devices'!$A$2:$A$184<>"")*(COUNTIF('Power_Connections'!$A$2:$A$2000,'Devices'!$A$2:$A$184)=0))=0,"OK","FIX: device without a power cord") | C38: Without it the power path, single-fed devices and UPS / PDU what-ifs cannot be traced.
A39: Power cords point at a known PDU | B39: =IF(SUMPRODUCT(('Power_Connections'!$C$2:$C$2000<>"")*(COUNTIF('Rack_PDUs'!$A$2:$A$2000,'Power_Connections'!$C$2:$C$2000)=0))=0,"OK","FIX: unknown pdu_id") | C39: The outlet map and failover check group cords by PDU.
A40: Every rack has an A and a B PDU | B40: =IF(SUMPRODUCT(('Racks'!$A$2:$A$33<>"")*((COUNTIFS('Rack_PDUs'!$C$2:$C$2000,'Racks'!$A$2:$A$33,'Rack_PDUs'!$D$2:$D$2000,"A")=0)+(COUNTIFS('Rack_PDUs'!$C$2:$C$2000,'Racks'!$A$2:$A$33,'Rack_PDUs'!$D$2:$D$2000,"B")=0)))=0,"OK","CHECK: rack with one power side") | C40: A cabinet with one side is a single point of failure for everything in it.
A41: Cable paths name a known link | B41: =IF(SUMPRODUCT(('Cable_Paths'!$A$2:$A$2000<>"")*(COUNTIF('Links'!$A$2:$A$2000,'Cable_Paths'!$A$2:$A$2000)=0))=0,"OK","FIX: unknown link_id") | C41: Each cable path belongs to one link end.
A42: Every operator device has warranty / support data | B42: =IF(SUMPRODUCT(('Devices'!$P$2:$P$184="operator")*('Devices'!$O$2:$O$184<>"Planned")*(COUNTIF('Asset_Lifecycle'!$A$2:$A$2000,'Devices'!$A$2:$A$184)=0))=0,"OK","CHECK: device without lifecycle row") | C42: Warranty, contract and end-of-support flags need it.
A43: Every room has a fire system | B43: =IF(SUMPRODUCT(('Rooms'!$C$2:$C$9<>"")*(COUNTIF('Fire_Systems'!$C$2:$C$2000,'Rooms'!$C$2:$C$9)=0))=0,"OK","CHECK: room without fire protection") | C43: Fire detection / suppression and its inspection plan are tracked per room.
...

Sheet Sites
A1: site_id * | B1: site_name * | C1: operator | D1: business_model * | E1: status * | F1: tier * | G1: category * | H1: region * | I1: state * | J1: city * | K1: address * | L1: latitude * | M1: longitude * | N1: commissioned_on | O1: it_capacity_kw * | P1: design_pue | Q1: cooling_capacity_kw * | R1: cooling_redundancy * | S1: timezone
A2: MH-DC-001 | B2: MH-DC-001 | D2: colocation | E2: in-progress | F2: Tier III | G2: Central | H2: West | I2: Maharashtra | J2: Pune | K2: Pune Data Park | L2: 18.593 | M2: 73.789 | O2: 390 | P2: 1.52 | Q2: 240 | R2: N+1 | S2: Asia/Kolkata
A3: MH-DC-002 | B3: MH-DC-002 | D3: colocation | E3: on-air | F3: Tier III | G3: Central | H3: West | I3: Maharashtra | J3: Pune | K3: Pune Data Park | L3: 18.601 | M3: 73.762 | N3: 45000 | O3: 330 | P3: 1.59 | Q3: 190 | R3: N+1 | S3: Asia/Kolkata

Sheet Floors
A1: site_id * | B1: floor_id * | C1: floor_name * | D1: level *
A2: MH-DC-001 | B2: MH-DC-001-F0 | C2: Ground | D2: 0
A3: MH-DC-001 | B3: MH-DC-001-F1 | C3: 1st floor | D3: 1
A4: MH-DC-002 | B4: MH-DC-002-F0 | C4: Ground | D4: 0
A5: MH-DC-002 | B5: MH-DC-002-F1 | C5: 1st floor | D5: 1

Sheet Rooms
A1: site_id * | B1: floor_id * | C1: room_id * | D1: room_name * | E1: room_type * | F1: area_sqm | G1: rack_rows | H1: containment | I1: cooling_method
A2: MH-DC-001 | B2: MH-DC-001-F0 | C2: MH-DC-001-F0-R1 | D2: Meet-me room | E2: Meet-me room | G2: 1 | I2: Air
A3: MH-DC-001 | B3: MH-DC-001-F0 | C3: MH-DC-001-F0-R2 | D3: Hall A | E3: Data hall | G3: 1 | I3: Air
A4: MH-DC-001 | B4: MH-DC-001-F1 | C4: MH-DC-001-F1-R1 | D4: Hall B | E4: Data hall | G4: 1 | I4: Air
A5: MH-DC-001 | B5: MH-DC-001-F1 | C5: MH-DC-001-F1-R2 | D5: Hall C | E5: Data hall | G5: 1 | I5: Air
A6: MH-DC-002 | B6: MH-DC-002-F0 | C6: MH-DC-002-F0-R1 | D6: Meet-me room | E6: Meet-me room | G6: 1 | I6: Hybrid
A7: MH-DC-002 | B7: MH-DC-002-F0 | C7: MH-DC-002-F0-R2 | D7: Hall A | E7: Data hall | G7: 1 | I7: Air
A8: MH-DC-002 | B8: MH-DC-002-F1 | C8: MH-DC-002-F1-R1 | D8: Hall B | E8: Data hall | G8: 1 | I8: Hybrid
A9: MH-DC-002 | B9: MH-DC-002-F1 | C9: MH-DC-002-F1-R2 | D9: Hall C | E9: Data hall | G9: 1 | I9: Air

Sheet Racks
A1: rack_id * | B1: site_id * | C1: room_id * | D1: rack_name * | E1: row | F1: position | G1: role * | H1: height_u * | I1: power_budget_kw * | J1: owner * | K1: tenant_customer_id | L1: contracted_kw | M1: density | N1: liquid_cooled | O1: cdu_id | P1: pdu_feed_a | Q1: pdu_feed_b | R1: used_u (calc)
A2: MH-DC-001-RACK-A | B2: MH-DC-001 | C2: MH-DC-001-F0-R1 | D2: RACK-A | G2: Core | H2: 45 | I2: 15 | J2: operator | M2: standard | N2: N | P2: MH-DC-001-AC-1 | Q2: MH-DC-001-AC-2 | R2: =SUMIF('Devices'!$L$2:$L$2000,A2,'Devices'!$N$2:$N$2000)
A3: MH-DC-001-RACK-B | B3: MH-DC-001 | C3: MH-DC-001-F0-R1 | D3: RACK-B | G3: Meet-me room | H3: 42 | I3: 16 | J3: operator | M3: standard | N3: N | P3: MH-DC-001-AC-1 | Q3: MH-DC-001-AC-2 | R3: =SUMIF('Devices'!$L$2:$L$2000,A3,'Devices'!$N$2:$N$2000)
A4: MH-DC-001-RACK-C | B4: MH-DC-001 | C4: MH-DC-001-F0-R1 | D4: RACK-C | G4: Tenant cabinet | H4: 45 | I4: 19 | J4: tenant | K4: CUST-7349 | L4: 19 | M4: standard | N4: N | P4: MH-DC-001-AC-1 | Q4: MH-DC-001-AC-2 | R4: =SUMIF('Devices'!$L$2:$L$2000,A4,'Devices'!$N$2:$N$2000)
A5: MH-DC-001-RACK-D | B5: MH-DC-001 | C5: MH-DC-001-F0-R1 | D5: RACK-D | G5: Tenant cabinet | H5: 45 | I5: 15 | J5: tenant | K5: CUST-2954 | L5: 15 | M5: standard | N5: N | P5: MH-DC-001-AC-1 | Q5: MH-DC-001-AC-2 | R5: =SUMIF('Devices'!$L$2:$L$2000,A5,'Devices'!$N$2:$N$2000)
A6: MH-DC-001-RACK-E | B6: MH-DC-001 | C6: MH-DC-001-F0-R1 | D6: RACK-E | G6: Tenant cabinet | H6: 42 | I6: 19 | J6: tenant | K6: CUST-2954 | L6: 19 | M6: standard | N6: N | P6: MH-DC-001-AC-1 | Q6: MH-DC-001-AC-2 | R6: =SUMIF('Devices'!$L$2:$L$2000,A6,'Devices'!$N$2:$N$2000)
A7: MH-DC-001-RACK-F | B7: MH-DC-001 | C7: MH-DC-001-F0-R2 | D7: RACK-F | G7: Tenant cabinet | H7: 45 | I7: 20 | J7: tenant | K7: CUST-9111 | L7: 20 | M7: standard | N7: N | P7: MH-DC-001-AC-1 | Q7: MH-DC-001-AC-2 | R7: =SUMIF('Devices'!$L$2:$L$2000,A7,'Devices'!$N$2:$N$2000)
A8: MH-DC-001-RACK-G | B8: MH-DC-001 | C8: MH-DC-001-F0-R2 | D8: RACK-G | G8: Tenant cabinet | H8: 45 | I8: 18 | J8: tenant | K8: CUST-9111 | L8: 18 | M8: standard | N8: N | P8: MH-DC-001-AC-1 | Q8: MH-DC-001-AC-2 | R8: =SUMIF('Devices'!$L$2:$L$2000,A8,'Devices'!$N$2:$N$2000)
A9: MH-DC-001-RACK-H | B9: MH-DC-001 | C9: MH-DC-001-F0-R2 | D9: RACK-H | G9: Tenant cabinet | H9: 42 | I9: 11 | J9: tenant | K9: CUST-6478 | L9: 11 | M9: standard | N9: N | P9: MH-DC-001-AC-1 | Q9: MH-DC-001-AC-2 | R9: =SUMIF('Devices'!$L$2:$L$2000,A9,'Devices'!$N$2:$N$2000)
A10: MH-DC-001-RACK-I | B10: MH-DC-001 | C10: MH-DC-001-F0-R2 | D10: RACK-I | G10: Tenant cabinet | H10: 45 | I10: 12 | J10: tenant | K10: CUST-2063 | L10: 12 | M10: standard | N10: N | P10: MH-DC-001-AC-1 | Q10: MH-DC-001-AC-2 | R10: =SUMIF('Devices'!$L$2:$L$2000,A10,'Devices'!$N$2:$N$2000)
A11: MH-DC-001-RACK-J | B11: MH-DC-001 | C11: MH-DC-001-F0-R2 | D11: RACK-J | G11: Tenant cabinet | H11: 45 | I11: 8 | J11: tenant | K11: CUST-8230 | L11: 8 | M11: standard | N11: N | P11: MH-DC-001-AC-1 | Q11: MH-DC-001-AC-2 | R11: =SUMIF('Devices'!$L$2:$L$2000,A11,'Devices'!$N$2:$N$2000)
A12: MH-DC-001-RACK-K | B12: MH-DC-001 | C12: MH-DC-001-F1-R1 | D12: RACK-K | G12: Tenant cabinet | H12: 42 | I12: 11 | J12: tenant | K12: CUST-8230 | L12: 11 | M12: standard | N12: N | P12: MH-DC-001-AC-1 | Q12: MH-DC-001-AC-2 | R12: =SUMIF('Devices'!$L$2:$L$2000,A12,'Devices'!$N$2:$N$2000)
A13: MH-DC-001-RACK-L | B13: MH-DC-001 | C13: MH-DC-001-F1-R1 | D13: RACK-L | G13: Tenant cabinet | H13: 45 | I13: 8 | J13: tenant | K13: CUST-8230 | L13: 8 | M13: standard | N13: N | P13: MH-DC-001-AC-1 | Q13: MH-DC-001-AC-2 | R13: =SUMIF('Devices'!$L$2:$L$2000,A13,'Devices'!$N$2:$N$2000)
A14: MH-DC-001-RACK-M | B14: MH-DC-001 | C14: MH-DC-001-F1-R1 | D14: RACK-M | G14: Tenant cabinet | H14: 45 | I14: 8 | J14: tenant | K14: CUST-6468 | L14: 8 | M14: standard | N14: N | P14: MH-DC-001-AC-1 | Q14: MH-DC-001-AC-2 | R14: =SUMIF('Devices'!$L$2:$L$2000,A14,'Devices'!$N$2:$N$2000)
A15: MH-DC-001-RACK-N | B15: MH-DC-001 | C15: MH-DC-001-F1-R1 | D15: RACK-N | G15: Tenant cabinet | H15: 42 | I15: 8 | J15: tenant | K15: CUST-6468 | L15: 8 | M15: standard | N15: N | P15: MH-DC-001-AC-1 | Q15: MH-DC-001-AC-2 | R15: =SUMIF('Devices'!$L$2:$L$2000,A15,'Devices'!$N$2:$N$2000)
... A17: MH-DC-001-RACK-P | B17: MH-DC-001 | C17: MH-DC-001-F1-R2 | D17: RACK-P | G17: Tenant cabinet | H17: 45 | I17: 8 | J17: tenant | K17: CUST-1202 | L17: 8 | M17: standard | N17: N | P17: MH-DC-001-AC-1 | Q17: MH-DC-001-AC-2 | R17: =SUMIF('Devices'!$L$2:$L$2000,A17,'Devices'!$N$2:$N$2000)
A18: MH-DC-001-RACK-Q | B18: MH-DC-001 | C18: MH-DC-001-F1-R2 | D18: RACK-Q | G18: Access | H18: 42 | I18: 8 | J18: operator | M18: standard | N18: N | P18: MH-DC-001-AC-1 | Q18: MH-DC-001-AC-2 | R18: =SUMIF('Devices'!$L$2:$L$2000,A18,'Devices'!$N$2:$N$2000)
A19: MH-DC-001-RACK-R | B19: MH-DC-001 | C19: MH-DC-001-F1-R2 | D19: RACK-R | G19: Access | H19: 45 | I19: 8 | J19: operator | M19: standard | N19: N | P19: MH-DC-001-AC-1 | Q19: MH-DC-001-AC-2 | R19: =SUMIF('Devices'!$L$2:$L$2000,A19,'Devices'!$N$2:$N$2000)
A20: MH-DC-001-RACK-S | B20: MH-DC-001 | C20: MH-DC-001-F1-R2 | D20: RACK-S | G20: Access | H20: 45 | I20: 8 | J20: operator | M20: standard | N20: N | P20: MH-DC-001-AC-1 | Q20: MH-DC-001-AC-2 | R20: =SUMIF('Devices'!$L$2:$L$2000,A20,'Devices'!$N$2:$N$2000)
A21: MH-DC-001-RACK-T | B21: MH-DC-001 | C21: MH-DC-001-F1-R2 | D21: RACK-T | G21: ODF / patching | H21: 42 | I21: 8 | J21: operator | M21: standard | N21: N | P21: MH-DC-001-AC-1 | Q21: MH-DC-001-AC-2 | R21: =SUMIF('Devices'!$L$2:$L$2000,A21,'Devices'!$N$2:$N$2000)
A22: MH-DC-001-RACK-U | B22: MH-DC-001 | C22: MH-DC-001-F0-R1 | D22: RACK-U | G22: Operator servers | H22: 42 | I22: 9 | J22: operator | M22: standard | N22: N | P22: MH-DC-001-AC-1 | Q22: MH-DC-001-AC-2 | R22: =SUMIF('Devices'!$L$2:$L$2000,A22,'Devices'!$N$2:$N$2000)
A23: MH-DC-002-RACK-A | B23: MH-DC-002 | C23: MH-DC-002-F0-R1 | D23: RACK-A | G23: Core | H23: 45 | I23: 15 | J23: operator | M23: standard | N23: N | P23: MH-DC-002-AC-1 | Q23: MH-DC-002-AC-2 | R23: =SUMIF('Devices'!$L$2:$L$2000,A23,'Devices'!$N$2:$N$2000)
A24: MH-DC-002-RACK-B | B24: MH-DC-002 | C24: MH-DC-002-F0-R1 | D24: RACK-B | G24: AI cage | H24: 42 | I24: 40 | J24: tenant | K24: CUST-7349 | L24: 40 | M24: ai | N24: Y | O24: MH-DC-002-CDU-1 | P24: MH-DC-002-AC-1 | Q24: MH-DC-002-AC-2 | R24: =SUMIF('Devices'!$L$2:$L$2000,A24,'Devices'!$N$2:$N$2000)
A25: MH-DC-002-RACK-C | B25: MH-DC-002 | C25: MH-DC-002-F0-R1 | D25: RACK-C | G25: AI cage | H25: 45 | I25: 40 | J25: tenant | K25: CUST-7349 | L25: 40 | M25: ai | N25: Y | O25: MH-DC-002-CDU-1 | P25: MH-DC-002-AC-1 | Q25: MH-DC-002-AC-2 | R25: =SUMIF('Devices'!$L$2:$L$2000,A25,'Devices'!$N$2:$N$2000)
A26: MH-DC-002-RACK-D | B26: MH-DC-002 | C26: MH-DC-002-F0-R2 | D26: RACK-D | G26: Tenant cabinet | H26: 45 | I26: 17 | J26: tenant | K26: CUST-8220 | L26: 17 | M26: standard | N26: N | P26: MH-DC-002-AC-1 | Q26: MH-DC-002-AC-2 | R26: =SUMIF('Devices'!$L$2:$L$2000,A26,'Devices'!$N$2:$N$2000)
A27: MH-DC-002-RACK-E | B27: MH-DC-002 | C27: MH-DC-002-F0-R2 | D27: RACK-E | G27: Tenant cabinet | H27: 42 | I27: 20 | J27: tenant | K27: CUST-4716 | L27: 20 | M27: standard | N27: N | P27: MH-DC-002-AC-1 | Q27: MH-DC-002-AC-2 | R27: =SUMIF('Devices'!$L$2:$L$2000,A27,'Devices'!$N$2:$N$2000)
A28: MH-DC-002-RACK-F | B28: MH-DC-002 | C28: MH-DC-002-F1-R1 | D28: RACK-F | G28: Tenant cabinet | H28: 45 | I28: 17 | J28: tenant | K28: CUST-2954 | L28: 17 | M28: standard | N28: N | P28: MH-DC-002-AC-1 | Q28: MH-DC-002-AC-2 | R28: =SUMIF('Devices'!$L$2:$L$2000,A28,'Devices'!$N$2:$N$2000)
A29: MH-DC-002-RACK-G | B29: MH-DC-002 | C29: MH-DC-002-F1-R1 | D29: RACK-G | G29: Tenant cabinet | H29: 45 | I29: 17 | J29: tenant | K29: CUST-2954 | L29: 17 | M29: standard | N29: N | P29: MH-DC-002-AC-1 | Q29: MH-DC-002-AC-2 | R29: =SUMIF('Devices'!$L$2:$L$2000,A29,'Devices'!$N$2:$N$2000)
A30: MH-DC-002-RACK-H | B30: MH-DC-002 | C30: MH-DC-002-F1-R1 | D30: RACK-H | G30: AI cage | H30: 42 | I30: 40 | J30: tenant | K30: CUST-1202 | L30: 40 | M30: ai | N30: Y | O30: MH-DC-002-CDU-1 | P30: MH-DC-002-AC-1 | Q30: MH-DC-002-AC-2 | R30: =SUMIF('Devices'!$L$2:$L$2000,A30,'Devices'!$N$2:$N$2000)
A31: MH-DC-002-RACK-I | B31: MH-DC-002 | C31: MH-DC-002-F1-R2 | D31: RACK-I | G31: Tenant cabinet | H31: 45 | I31: 8 | J31: tenant | K31: CUST-1202 | L31: 8 | M31: standard | N31: N | P31: MH-DC-002-AC-1 | Q31: MH-DC-002-AC-2 | R31: =SUMIF('Devices'!$L$2:$L$2000,A31,'Devices'!$N$2:$N$2000)
A32: MH-DC-002-RACK-J | B32: MH-DC-002 | C32: MH-DC-002-F1-R2 | D32: RACK-J | G32: ODF / patching | H32: 45 | I32: 8 | J32: operator | M32: standard | N32: N | P32: MH-DC-002-AC-1 | Q32: MH-DC-002-AC-2 | R32: =SUMIF('Devices'!$L$2:$L$2000,A32,'Devices'!$N$2:$N$2000)
A33: MH-DC-002-RACK-K | B33: MH-DC-002 | C33: MH-DC-002-F0-R1 | D33: RACK-K | G33: Operator servers | H33: 42 | I33: 8 | J33: operator | M33: standard | N33: N | P33: MH-DC-002-AC-1 | Q33: MH-DC-002-AC-2 | R33: =SUMIF('Devices'!$L$2:$L$2000,A33,'Devices'!$N$2:$N$2000)

Sheet Power_Feeds
A1: feed_id * | B1: site_id * | C1: type * | D1: source * | E1: rating * | F1: capacity_kw * | G1: normal_role | H1: utility_account
A2: MH-DC-001-AC-1 | B2: MH-DC-001 | C2: AC | D2: Utility feed A | E2: 380 A · 415 V | F2: 273 | G2: Active
A3: MH-DC-001-AC-2 | B3: MH-DC-001 | C3: AC | D3: Utility feed B | E3: 380 A · 415 V | F3: 273 | G3: Standby
A4: MH-DC-001-DC-1 | B4: MH-DC-001 | C4: DC | D4: Rectifier RECT-01 | E4: 48 V · 2440 A | F4: 117 | G4: Active
A5: MH-DC-002-AC-1 | B5: MH-DC-002 | C5: AC | D5: Utility feed A | E5: 321 A · 415 V | F5: 231 | G5: Active
A6: MH-DC-002-AC-2 | B6: MH-DC-002 | C6: AC | D6: Utility feed B | E6: 321 A · 415 V | F6: 231 | G6: Standby
A7: MH-DC-002-DC-1 | B7: MH-DC-002 | C7: DC | D7: Rectifier RECT-01 | E7: 48 V · 2060 A | F7: 99 | G7: Active

Sheet UPS
A1: ups_id * | B1: site_id * | C1: room_id | D1: name * | E1: vendor | F1: model | G1: serial | H1: capacity_kw * | I1: redundancy * | J1: battery_autonomy_min *
A2: MH-DC-001-UPS-1 | B2: MH-DC-001 | D2: UPS-1 | H2: 130 | I2: N+1 | J2: 15
A3: MH-DC-001-UPS-2 | B3: MH-DC-001 | D3: UPS-2 | H3: 130 | I3: N+1 | J3: 16
A4: MH-DC-001-UPS-3 | B4: MH-DC-001 | D4: UPS-3 | H4: 130 | I4: N+1 | J4: 23
A5: MH-DC-001-UPS-4 | B5: MH-DC-001 | D5: UPS-4 | H5: 130 | I5: N+1 | J5: 18
A6: MH-DC-002-UPS-1 | B6: MH-DC-002 | D6: UPS-1 | H6: 110 | I6: N+1 | J6: 26
A7: MH-DC-002-UPS-2 | B7: MH-DC-002 | D7: UPS-2 | H7: 110 | I7: N+1 | J7: 26
A8: MH-DC-002-UPS-3 | B8: MH-DC-002 | D8: UPS-3 | H8: 110 | I8: N+1 | J8: 15
A9: MH-DC-002-UPS-4 | B9: MH-DC-002 | D9: UPS-4 | H9: 110 | I9: N+1 | J9: 16

Sheet Generators
A1: dg_id * | B1: site_id * | C1: name * | D1: kva * | E1: fuel_tank_litres | F1: runtime_h_full_load * | G1: last_test_date | H1: last_test_result
A2: MH-DC-001-DG-1 | B2: MH-DC-001 | C2: DG-1 | D2: 500 | F2: 10 | G2: 46261 | H2: Pass
A3: MH-DC-002-DG-1 | B3: MH-DC-002 | C3: DG-1 | D3: 425 | F3: 12 | G3: 46282 | H3: Pass

Sheet DC_Plant
A1: plant_id * | B1: site_id * | C1: room_id | D1: kind * | E1: name * | F1: volts | G1: ah | H1: rated_output | I1: capacity_kw | J1: autonomy_h | K1: last_test_date
A2: MH-DC-001-RECT-01 | B2: MH-DC-001 | D2: Rectifier | E2: RECT-01 | H2: 48 V · 2440 A | I2: 117
A3: MH-DC-001-BATT-01 | B3: MH-DC-001 | D3: Battery bank | E3: BATT-01 | F3: 48 | G3: 2400 | J3: 3.4 | K3: 46256
A4: MH-DC-002-RECT-01 | B4: MH-DC-002 | D4: Rectifier | E4: RECT-01 | H4: 48 V · 2060 A | I4: 99
A5: MH-DC-002-BATT-01 | B5: MH-DC-002 | D5: Battery bank | E5: BATT-01 | F5: 48 | G5: 2000 | J5: 3.8 | K5: 46229

Sheet Cooling_Units
A1: unit_id * | B1: site_id * | C1: room_id * | D1: name * | E1: type * | F1: vendor | G1: model | H1: capacity_kw * | I1: design_supply_c
A2: MH-DC-001-CRAH-11 | B2: MH-DC-001 | C2: MH-DC-001-F0-R1 | D2: CRAH-11 | E2: CRAH | H2: 30 | I2: 18
A3: MH-DC-001-CRAH-12 | B3: MH-DC-001 | C3: MH-DC-001-F0-R2 | D3: CRAH-12 | E3: CRAH | H3: 30 | I3: 18
A4: MH-DC-001-CRAH-13 | B4: MH-DC-001 | C4: MH-DC-001-F1-R1 | D4: CRAH-13 | E4: CRAH | H4: 30 | I4: 17
A5: MH-DC-001-CRAH-14 | B5: MH-DC-001 | C5: MH-DC-001-F1-R2 | D5: CRAH-14 | E5: CRAH | H5: 30 | I5: 20
A6: MH-DC-001-CRAH-15 | B6: MH-DC-001 | C6: MH-DC-001-F0-R1 | D6: CRAH-15 | E6: CRAC | H6: 30 | I6: 20
A7: MH-DC-001-CRAH-16 | B7: MH-DC-001 | C7: MH-DC-001-F0-R2 | D7: CRAH-16 | E7: CRAH | H7: 30 | I7: 18
A8: MH-DC-001-CRAH-17 | B8: MH-DC-001 | C8: MH-DC-001-F1-R1 | D8: CRAH-17 | E8: CRAH | H8: 30 | I8: 18
A9: MH-DC-001-CRAH-18 | B9: MH-DC-001 | C9: MH-DC-001-F1-R2 | D9: CRAH-18 | E9: CRAH | H9: 30 | I9: 19
A10: MH-DC-002-CRAH-11 | B10: MH-DC-002 | C10: MH-DC-002-F0-R1 | D10: CRAH-11 | E10: CRAH | H10: 24 | I10: 20
A11: MH-DC-002-CRAH-12 | B11: MH-DC-002 | C11: MH-DC-002-F0-R2 | D11: CRAH-12 | E11: CRAH | H11: 24 | I11: 18
A12: MH-DC-002-CRAH-13 | B12: MH-DC-002 | C12: MH-DC-002-F1-R1 | D12: CRAH-13 | E12: CRAH | H12: 24 | I12: 20
A13: MH-DC-002-CRAH-14 | B13: MH-DC-002 | C13: MH-DC-002-F1-R2 | D13: CRAH-14 | E13: CRAH | H13: 24 | I13: 19
... A18: MH-DC-002-CDU-1 | B18: MH-DC-002 | C18: MH-DC-002-F0-R1 | D18: CDU-1 | E18: CDU | H18: 150 | I18: 26.8

Sheet CDUs
A1: cdu_id * | B1: site_id * | C1: room_id * | D1: name * | E1: capacity_kw * | F1: nominal_flow_lpm * | G1: design_supply_c | H1: racks_served (calc)
A2: MH-DC-002-CDU-1 | B2: MH-DC-002 | C2: MH-DC-002-F0-R1 | D2: CDU-1 | E2: 150 | F2: 220 | G2: 26.8 | H2: =COUNTIF('Racks'!$O$2:$O$2000,A2)

Sheet Sensors
A1: sensor_id * | B1: site_id * | C1: room_id * | D1: kind * | E1: position | F1: bms_point
A2: MH-DC-001-ENV-1 | B2: MH-DC-001 | C2: MH-DC-001-F0-R1 | D2: Temperature + humidity
A3: MH-DC-001-ENV-2 | B3: MH-DC-001 | C3: MH-DC-001-F0-R2 | D3: Temperature + humidity
A4: MH-DC-001-ENV-3 | B4: MH-DC-001 | C4: MH-DC-001-F1-R1 | D4: Temperature + humidity
A5: MH-DC-001-ENV-4 | B5: MH-DC-001 | C5: MH-DC-001-F1-R2 | D5: Temperature + humidity
A6: MH-DC-002-ENV-1 | B6: MH-DC-002 | C6: MH-DC-002-F0-R1 | D6: Temperature + humidity
A7: MH-DC-002-ENV-2 | B7: MH-DC-002 | C7: MH-DC-002-F0-R2 | D7: Temperature + humidity
A8: MH-DC-002-ENV-3 | B8: MH-DC-002 | C8: MH-DC-002-F1-R1 | D8: Temperature + humidity
A9: MH-DC-002-ENV-4 | B9: MH-DC-002 | C9: MH-DC-002-F1-R2 | D9: Temperature + humidity

Sheet Devices
A1: device_id * | B1: site_id * | C1: hostname * | D1: role * | E1: layer * | F1: vendor * | G1: model * | H1: os_version | I1: serial | J1: mgmt_ip | K1: mac | L1: rack_id * | M1: u_position * | N1: u_size * | O1: lifecycle * | P1: owner * | Q1: tenant_customer_id | R1: monitored * | S1: collector_id | T1: wan_edge
A2: MH-DC-001-PE-T4-01 | B2: MH-DC-001 | C2: MH-DC-001-PE-T4-01 | D2: Router | E2: core | F2: JUNIPER | G2: MX204 | H2: 21.4R3-S5.5 | I2: JU0011000 | J2: 172.31.40.20 | K2: A4:5E:60:16:8F:48 | L2: MH-DC-001-RACK-A | M2: 2 | N2: 1 | O2: Ready | P2: operator | R2: Y | S2: COL-MH-DC-001-2 | T2: Y
A3: MH-DC-001-PE-T4-02 | B3: MH-DC-001 | C3: MH-DC-001-PE-T4-02 | D3: Router | E3: core | F3: JUNIPER | G3: MX204 | H3: 21.4R3-S5.5 | I3: JU0011012 | J3: 172.16.40.21 | K3: A4:5E:60:E4:96:7C | L3: MH-DC-001-RACK-A | M3: 3 | N3: 1 | O3: Ready | P3: operator | R3: Y | S3: COL-MH-DC-001-1 | T3: Y
A4: MH-DC-001-PE-T4-03 | B4: MH-DC-001 | C4: MH-DC-001-PE-T4-03 | D4: Router | E4: core | F4: CISCO | G4: ASR 9006 | H4: IOS XR 7.9.2 | I4: CS0011018 | J4: 172.16.40.22 | K4: A4:5E:60:03:E2:69 | L4: MH-DC-001-RACK-A | M4: 4 | N4: 1 | O4: Ready | P4: operator | R4: Y | S4: COL-MH-DC-001-2 | T4: Y
A5: MH-DC-001-PE-T4-04 | B5: MH-DC-001 | C5: MH-DC-001-PE-T4-04 | D5: Router | E5: core | F5: CISCO | G5: ASR 9006 | H5: IOS XR 7.9.2 | I5: CS0011027 | J5: 172.16.40.23 | K5: A4:5E:60:71:F5:F9 | L5: MH-DC-001-RACK-A | M5: 5 | N5: 1 | O5: Ready | P5: operator | R5: Y | S5: COL-MH-DC-001-1 | T5: Y
A6: MH-DC-001-FW-01 | B6: MH-DC-001 | C6: MH-DC-001-FW-01 | D6: Firewall | E6: core | F6: FORTINET | G6: FortiGate 3700F | H6: FortiOS 7.4.3 | I6: FG0011031 | J6: 172.16.40.24 | K6: A4:5E:60:B1:E8:37 | L6: MH-DC-001-RACK-A | M6: 6 | N6: 3 | O6: Ready | P6: operator | R6: Y | S6: COL-MH-DC-001-1 | T6: N
A7: MH-DC-001-FW-02 | B7: MH-DC-001 | C7: MH-DC-001-FW-02 | D7: Firewall | E7: core | F7: FORTINET | G7: FortiGate 3700F | H7: FortiOS 7.4.3 | I7: FG0011035 | J7: 172.16.40.25 | K7: A4:5E:60:FA:5F:B0 | L7: MH-DC-001-RACK-A | M7: 9 | N7: 3 | O7: Ready | P7: operator | R7: Y | S7: COL-MH-DC-001-2 | T7: N
A8: MH-DC-001-OLA-01 | B8: MH-DC-001 | C8: MH-DC-001-OLA-01 | D8: DWDM | E8: core | F8: NOKIA | G8: 1830 PSS-16II | H8: R23.6 | I8: NK0011042 | J8: 172.16.40.26 | K8: A4:5E:60:95:3C:15 | L8: MH-DC-001-RACK-A | M8: 12 | N8: 6 | O8: Ready | P8: operator | R8: Y | S8: COL-MH-DC-001-2 | T8: N
A9: MH-DC-001-OLA-02 | B9: MH-DC-001 | C9: MH-DC-001-OLA-02 | D9: DWDM | E9: core | F9: NOKIA | G9: 1830 PSS-16II | H9: R23.6 | I9: NK0011055 | J9: 172.16.40.27 | K9: A4:5E:60:B4:0B:73 | L9: MH-DC-001-RACK-A | M9: 18 | N9: 6 | O9: Ready | P9: operator | R9: Y | S9: COL-MH-DC-001-1 | T9: N
A10: MH-DC-001-AGG-R01 | B10: MH-DC-001 | C10: MH-DC-001-AGG-R01 | D10: Router | E10: spine | F10: JUNIPER | G10: MX480 | H10: 22.2R3-S2 | I10: JU0011062 | J10: 172.16.40.28 | K10: A4:5E:60:33:FB:48 | L10: MH-DC-001-RACK-A | M10: 24 | N10: 4 | O10: Ready | P10: operator | R10: Y | S10: COL-MH-DC-001-1 | T10: N
A11: MH-DC-001-AGG-R02 | B11: MH-DC-001 | C11: MH-DC-001-AGG-R02 | D11: Router | E11: spine | F11: JUNIPER | G11: MX480 | H11: 22.2R3-S2 | I11: JU0011065 | J11: 172.16.40.29 | K11: A4:5E:60:9F:2F:3B | L11: MH-DC-001-RACK-A | M11: 28 | N11: 4 | O11: Ready | P11: operator | R11: Y | S11: COL-MH-DC-001-2 | T11: N
A12: MH-DC-001-AGG-R03 | B12: MH-DC-001 | C12: MH-DC-001-AGG-R03 | D12: Router | E12: spine | F12: JUNIPER | G12: MX480 | H12: 22.2R3-S2 | I12: JU0011071 | J12: 172.16.40.30 | K12: A4:5E:60:EF:F0:A5 | L12: MH-DC-001-RACK-A | M12: 32 | N12: 4 | O12: Ready | P12: operator | R12: Y | S12: COL-MH-DC-001-1 | T12: N
A13: MH-DC-001-MMR-SW-01 | B13: MH-DC-001 | C13: MH-DC-001-MMR-SW-01 | D13: Switch | E13: leaf | F13: JUNIPER | G13: QFX5100-48S | H13: Junos 21.4R3-S6 | I13: JU0011080 | J13: 172.16.40.31 | K13: A4:5E:60:C0:C8:FC | L13: MH-DC-001-RACK-A | M13: 36 | N13: 1 | O13: Ready | P13: operator | R13: Y | S13: COL-MH-DC-001-1 | T13: N
... A27: MH-DC-001-TOR-006 | B27: MH-DC-001 | C27: MH-DC-001-TOR-006 | D27: Switch | E27: access | F27: ARISTA | G27: 7050SX3-48YC | H27: EOS 4.31.1F | I27: AR0011180 | J27: 172.16.40.45 | K27: A4:5E:60:F6:66:F8 | L27: MH-DC-001-RACK-B | M27: 15 | N27: 1 | O27: Ready | P27: operator | R27: Y | S27: COL-MH-DC-001-2 | T27: N
A28: MH-DC-001-TN-001 | B28: MH-DC-001 | C28: MH-DC-001-TN-001 | D28: Tenant gear | E28: access | F28: Tenant-owned | G28: Mixed equipment | H28: — | L28: MH-DC-001-RACK-B | M28: 16 | N28: 6 | O28: Ready | P28: tenant | R28: N | T28: N
A29: MH-DC-001-TN-002 | B29: MH-DC-001 | C29: MH-DC-001-TN-002 | D29: Tenant gear | E29: access | F29: Tenant-owned | G29: Network stack | H29: — | L29: MH-DC-001-RACK-B | M29: 22 | N29: 6 | O29: Ready | P29: tenant | R29: N | T29: N
A30: MH-DC-001-TN-003 | B30: MH-DC-001 | C30: MH-DC-001-TN-003 | D30: Tenant gear | E30: access | F30: Tenant-owned | G30: Network stack | H30: — | L30: MH-DC-001-RACK-C | M30: 2 | N30: 8 | O30: Ready | P30: tenant | Q30: CUST-7349 | R30: N | T30: N
A31: MH-DC-001-TN-004 | B31: MH-DC-001 | C31: MH-DC-001-TN-004 | D31: Tenant gear | E31: access | F31: Tenant-owned | G31: Network stack | H31: — | L31: MH-DC-001-RACK-C | M31: 10 | N31: 4 | O31: Ready | P31: tenant | Q31: CUST-7349 | R31: N | T31: N
A32: MH-DC-001-TN-005 | B32: MH-DC-001 | C32: MH-DC-001-TN-005 | D32: Tenant gear | E32: access | F32: Tenant-owned | G32: Storage array | H32: — | L32: MH-DC-001-RACK-C | M32: 14 | N32: 4 | O32: Ready | P32: tenant | Q32: CUST-7349 | R32: N | T32: N
A33: MH-DC-001-TN-006 | B33: MH-DC-001 | C33: MH-DC-001-TN-006 | D33: Tenant gear | E33: access | F33: Tenant-owned | G33: HPC nodes | H33: — | L33: MH-DC-001-RACK-C | M33: 18 | N33: 2 | O33: Ready | P33: tenant | Q33: CUST-7349 | R33: N | T33: N
A34: MH-DC-001-TN-007 | B34: MH-DC-001 | C34: MH-DC-001-TN-007 | D34: Tenant gear | E34: access | F34: Tenant-owned | G34: Blade chassis | H34: — | L34: MH-DC-001-RACK-C | M34: 20 | N34: 8 | O34: Ready | P34: tenant | Q34: CUST-7349 | R34: N | T34: N
A35: MH-DC-001-TN-008 | B35: MH-DC-001 | C35: MH-DC-001-TN-008 | D35: Tenant gear | E35: access | F35: Tenant-owned | G35: Mixed equipment | H35: — | L35: MH-DC-001-RACK-C | M35: 28 | N35: 4 | O35: Ready | P35: tenant | Q35: CUST-7349 | R35: N | T35: N
A36: MH-DC-001-TN-009 | B36: MH-DC-001 | C36: MH-DC-001-TN-009 | D36: Tenant gear | E36: access | F36: Tenant-owned | G36: Blade chassis | H36: — | L36: MH-DC-001-RACK-C | M36: 32 | N36: 4 | O36: Ready | P36: tenant | Q36: CUST-7349 | R36: N | T36: N
A37: MH-DC-001-TN-010 | B37: MH-DC-001 | C37: MH-DC-001-TN-010 | D37: Tenant gear | E37: access | F37: Tenant-owned | G37: Mixed equipment | H37: — | L37: MH-DC-001-RACK-D | M37: 2 | N37: 10 | O37: Ready | P37: tenant | Q37: CUST-2954 | R37: N | T37: N
A38: MH-DC-001-TN-011 | B38: MH-DC-001 | C38: MH-DC-001-TN-011 | D38: Tenant gear | E38: access | F38: Tenant-owned | G38: Network stack | H38: — | L38: MH-DC-001-RACK-D | M38: 12 | N38: 2 | O38: Ready | P38: tenant | Q38: CUST-2954 | R38: N | T38: N
A39: MH-DC-001-TN-012 | B39: MH-DC-001 | C39: MH-DC-001-TN-012 | D39: Tenant gear | E39: access | F39: Tenant-owned | G39: Network stack | H39: — | L39: MH-DC-001-RACK-D | M39: 14 | N39: 10 | O39: Ready | P39: tenant | Q39: CUST-2954 | R39: N | T39: N
A40: MH-DC-001-TN-013 | B40: MH-DC-001 | C40: MH-DC-001-TN-013 | D40: Tenant gear | E40: access | F40: Tenant-owned | G40: Network stack | H40: — | L40: MH-DC-001-RACK-D | M40: 24 | N40: 2 | O40: Ready | P40: tenant | Q40: CUST-2954 | R40: N | T40: N
A41: MH-DC-001-TN-014 | B41: MH-DC-001 | C41: MH-DC-001-TN-014 | D41: Tenant gear | E41: access | F41: Tenant-owned | G41: Storage array | H41: — | L41: MH-DC-001-RACK-D | M41: 26 | N41: 10 | O41: Ready | P41: tenant | Q41: CUST-2954 | R41: N | T41: N
... A108: MH-DC-001-TN-081 | B108: MH-DC-001 | C108: MH-DC-001-TN-081 | D108: Tenant gear | E108: access | F108: Tenant-owned | G108: Blade chassis | H108: — | L108: MH-DC-001-RACK-P | M108: 12 | N108: 6 | O108: Ready | P108: tenant | Q108: CUST-1202 | R108: N | T108: N
A109: MH-DC-001-BMS-01 | B109: MH-DC-001 | C109: MH-DC-001-BMS-01 | D109: Server | E109: access | F109: DELL | G109: PowerEdge R640 | H109: ESXi 7.0u3 | I109: DL0011754 | J109: 172.16.40.127 | K109: A4:5E:60:F6:F0:87 | L109: MH-DC-001-RACK-U | M109: 2 | N109: 1 | O109: Ready | P109: operator | R109: Y | S109: COL-MH-DC-001-2 | T109: N
A110: MH-DC-001-BMS-02 | B110: MH-DC-001 | C110: MH-DC-001-BMS-02 | D110: Server | E110: access | F110: DELL | G110: PowerEdge R640 | H110: ESXi 7.0u3 | I110: DL0011762 | J110: 172.16.40.128 | K110: A4:5E:60:5C:CC:A7 | L110: MH-DC-001-RACK-U | M110: 3 | N110: 1 | O110: Ready | P110: operator | R110: Y | S110: COL-MH-DC-001-1 | T110: N
A111: MH-DC-001-ACS-01 | B111: MH-DC-001 | C111: MH-DC-001-ACS-01 | D111: Server | E111: access | F111: SUPERMICRO | G111: SYS-121H | H111: Ubuntu 22.04 | I111: SM0011765 | J111: 172.16.40.129 | K111: A4:5E:60:75:E5:C9 | L111: MH-DC-001-RACK-U | M111: 4 | N111: 1 | O111: Ready | P111: operator | R111: Y | S111: COL-MH-DC-001-1 | T111: N
A112: MH-DC-001-NVR-01 | B112: MH-DC-001 | C112: MH-DC-001-NVR-01 | D112: Server | E112: access | F112: HPE | G112: ProLiant DL380 Gen11 | H112: RHEL 9.3 | I112: HP0011772 | J112: 172.16.40.130 | K112: A4:5E:60:13:C5:EA | L112: MH-DC-001-RACK-U | M112: 5 | N112: 2 | O112: Ready | P112: operator | R112: Y | S112: COL-MH-DC-001-2 | T112: N
A113: MH-DC-001-NVR-02 | B113: MH-DC-001 | C113: MH-DC-001-NVR-02 | D113: Server | E113: access | F113: SUPERMICRO | G113: SYS-121H | H113: Ubuntu 22.04 | I113: SM0011779 | J113: 172.16.40.131 | K113: A4:5E:60:8D:93:D8 | L113: MH-DC-001-RACK-U | M113: 7 | N113: 2 | O113: Ready | P113: operator | R113: Y | S113: COL-MH-DC-001-1 | T113: N
A114: MH-DC-001-JMP-01 | B114: MH-DC-001 | C114: MH-DC-001-JMP-01 | D114: Server | E114: access | F114: SUPERMICRO | G114: SYS-121H | H114: Ubuntu 22.04 | I114: SM0011787 | J114: 172.16.40.132 | K114: A4:5E:60:0A:CB:A4 | L114: MH-DC-001-RACK-U | M114: 9 | N114: 1 | O114: Ready | P114: operator | R114: Y | S114: COL-MH-DC-001-1 | T114: N
A115: MH-DC-001-JMP-02 | B115: MH-DC-001 | C115: MH-DC-001-JMP-02 | D115: Server | E115: access | F115: HPE | G115: ProLiant DL380 Gen11 | H115: RHEL 9.3 | I115: HP0011793 | J115: 172.16.40.133 | K115: A4:5E:60:B6:CB:A6 | L115: MH-DC-001-RACK-U | M115: 10 | N115: 1 | O115: Ready | P115: operator | R115: Y | S115: COL-MH-DC-001-2 | T115: N
A116: MH-DC-001-BKP-01 | B116: MH-DC-001 | C116: MH-DC-001-BKP-01 | D116: Server | E116: access | F116: DELL | G116: PowerEdge R760 | H116: ESXi 8.0u2 | I116: DL0011804 | J116: 172.16.40.134 | K116: A4:5E:60:4C:E0:FB | L116: MH-DC-001-RACK-U | M116: 11 | N116: 2 | O116: Ready | P116: operator | R116: Y | S116: COL-MH-DC-001-1 | T116: N
A117: MH-DC-001-DCIM-01 | B117: MH-DC-001 | C117: MH-DC-001-DCIM-01 | D117: Server | E117: access | F117: SUPERMICRO | G117: SYS-121H | H117: Ubuntu 22.04 | I117: SM0011811 | J117: 172.16.40.135 | K117: A4:5E:60:08:99:7B | L117: MH-DC-001-RACK-U | M117: 13 | N117: 1 | O117: Ready | P117: operator | R117: Y | S117: COL-MH-DC-001-1 | T117: N
A118: MH-DC-001-DCIM-02 | B118: MH-DC-001 | C118: MH-DC-001-DCIM-02 | D118: Server | E118: access | F118: SUPERMICRO | G118: SYS-121H | H118: Ubuntu 22.04 | I118: SM0011812 | J118: 172.16.40.136 | K118: A4:5E:60:AB:75:74 | L118: MH-DC-001-RACK-U | M118: 14 | N118: 1 | O118: Ready | P118: operator | R118: Y | S118: COL-MH-DC-001-2 | T118: N
A119: MH-DC-001-MON-01 | B119: MH-DC-001 | C119: MH-DC-001-MON-01 | D119: Server | E119: access | F119: HPE | G119: ProLiant DL380 Gen11 | H119: RHEL 9.3 | I119: HP0011825 | J119: 172.16.40.137 | K119: A4:5E:60:3A:44:87 | L119: MH-DC-001-RACK-U | M119: 15 | N119: 1 | O119: Ready | P119: operator | R119: Y | S119: COL-MH-DC-001-2 | T119: N
...

Sheet Modules
A1: device_id * | B1: slot * | C1: name * | D1: serial
A2: MH-DC-001-PE-T4-01 | B2: RE0 | C2: Routing Engine | D2: JU0011000-RE0
A3: MH-DC-001-PE-T4-01 | B3: FPC0 | C3: MPC (fixed) | D3: JU0011000-F0
A4: MH-DC-001-PE-T4-01 | B4: PEM0 | C4: Power supply AC | D4: JU0011000-P0
A5: MH-DC-001-PE-T4-01 | B5: PEM1 | C5: Power supply AC | D5: JU0011000-P1
A6: MH-DC-001-PE-T4-01 | B6: FAN0 | C6: Fan tray | D6: JU0011000-FT
A7: MH-DC-001-PE-T4-02 | B7: RE0 | C7: Routing Engine | D7: JU0011012-RE0
A8: MH-DC-001-PE-T4-02 | B8: FPC0 | C8: MPC (fixed) | D8: JU0011012-F0
A9: MH-DC-001-PE-T4-02 | B9: PEM0 | C9: Power supply AC | D9: JU0011012-P0
A10: MH-DC-001-PE-T4-02 | B10: PEM1 | C10: Power supply AC | D10: JU0011012-P1
A11: MH-DC-001-PE-T4-02 | B11: FAN0 | C11: Fan tray | D11: JU0011012-FT
A12: MH-DC-001-PE-T4-03 | B12: RE0 | C12: Routing Engine | D12: CS0011018-RE0
... A304: MH-DC-002-MON-02 | B304: DISK3 | C304: NVMe 3.84 TB | D304: DL0011443-D3

Sheet Interfaces
A1: device_id * | B1: if_name * | C1: type * | D1: speed_mbps * | E1: admin_state * | F1: description | G1: optic_model
A2: MH-DC-001-PE-T4-01 | B2: xe-0/0/0 | C2: 10G SFP+ | D2: 10000 | E2: admin-down
A3: MH-DC-001-PE-T4-01 | B3: xe-0/0/1 | C3: 10G SFP+ | D3: 10000 | E3: up | F3: Backhaul to UP-DC-006 | G3: SFP-10G-LR
A4: MH-DC-001-PE-T4-01 | B4: xe-0/0/2 | C4: 10G SFP+ | D4: 10000 | E4: up | F4: Backhaul to KA-DC-021 | G4: SFP-10G-LR
A5: MH-DC-001-PE-T4-01 | B5: xe-0/0/3 | C5: 10G SFP+ | D5: 10000 | E5: up | F5: Backhaul to TS-DC-023 | G5: SFP-10G-LR
A6: MH-DC-001-PE-T4-01 | B6: xe-0/0/4 | C6: 10G SFP+ | D6: 10000 | E6: up | F6: Backhaul to BR-DC-019 | G6: SFP-10G-LR
A7: MH-DC-001-PE-T4-01 | B7: xe-0/0/5 | C7: 10G SFP+ | D7: 10000 | E7: up | F7: Backhaul to PB-DC-012 | G7: SFP-10G-LR
A8: MH-DC-001-PE-T4-01 | B8: xe-0/0/6 | C8: 10G SFP+ | D8: 10000 | E8: up | F8: Uplink to MH-DC-001-AGG-R01 | G8: SFP-10G-LR
A9: MH-DC-001-PE-T4-01 | B9: xe-0/0/7 | C9: 10G SFP+ | D9: 10000 | E9: admin-down
A10: MH-DC-001-PE-T4-01 | B10: xe-0/0/8 | C10: 10G SFP+ | D10: 10000 | E10: admin-down
A11: MH-DC-001-PE-T4-01 | B11: xe-0/0/9 | C11: 10G SFP+ | D11: 10000 | E11: admin-down
A12: MH-DC-001-PE-T4-01 | B12: xe-0/0/10 | C12: 10G SFP+ | D12: 10000 | E12: admin-down
A13: MH-DC-001-PE-T4-01 | B13: xe-0/0/11 | C13: 10G SFP+ | D13: 10000 | E13: admin-down
A14: MH-DC-001-PE-T4-01 | B14: et-0/1/0 | C14: 100G QSFP28 | D14: 100000 | E14: up | F14: Fabric to MH-DC-001-PE-T4-02 | G14: QSFP28-100G-LR4
A15: MH-DC-001-PE-T4-01 | B15: et-0/1/1 | C15: 100G QSFP28 | D15: 100000 | E15: up | F15: Fabric to MH-DC-001-PE-T4-03 | G15: QSFP28-100G-LR4
A16: MH-DC-001-PE-T4-01 | B16: et-0/1/2 | C16: 100G QSFP28 | D16: 100000 | E16: up | F16: Fabric to MH-DC-001-PE-T4-04 | G16: QSFP28-100G-LR4
A17: MH-DC-001-PE-T4-01 | B17: et-0/1/3 | C17: 100G QSFP28 | D17: 100000 | E17: reserved
A18: MH-DC-001-PE-T4-01 | B18: ge-0/2/0 | C18: 1G copper | D18: 1000 | E18: reserved
A19: MH-DC-001-PE-T4-01 | B19: ge-0/2/1 | C19: 1G copper | D19: 1000 | E19: admin-down
A20: MH-DC-001-PE-T4-01 | B20: ge-0/2/2 | C20: 1G copper | D20: 1000 | E20: admin-down
A21: MH-DC-001-PE-T4-01 | B21: ge-0/2/3 | C21: 1G copper | D21: 1000 | E21: admin-down
A22: MH-DC-001-PE-T4-01 | B22: ge-0/2/4 | C22: 1G copper | D22: 1000 | E22: admin-down
A23: MH-DC-001-PE-T4-01 | B23: ge-0/2/5 | C23: 1G copper | D23: 1000 | E23: admin-down
A24: MH-DC-001-PE-T4-01 | B24: ge-0/2/6 | C24: 1G copper | D24: 1000 | E24: admin-down
A25: MH-DC-001-PE-T4-01 | B25: ge-0/2/7 | C25: 1G copper | D25: 1000 | E25: admin-down
A26: MH-DC-001-PE-T4-01 | B26: ge-0/2/8 | C26: 1G copper | D26: 1000 | E26: admin-down
A27: MH-DC-001-PE-T4-01 | B27: ge-0/2/9 | C27: 1G copper | D27: 1000 | E27: admin-down
A28: MH-DC-001-PE-T4-01 | B28: ge-0/2/10 | C28: 1G copper | D28: 1000 | E28: admin-down
... A34: MH-DC-001-PE-T4-02 | B34: xe-0/0/0 | C34: 10G SFP+ | D34: 10000 | E34: admin-down
A35: MH-DC-001-PE-T4-02 | B35: xe-0/0/1 | C35: 10G SFP+ | D35: 10000 | E35: up | F35: Backhaul to HR-DC-011 | G35: SFP-10G-LR
A36: MH-DC-001-PE-T4-02 | B36: xe-0/0/2 | C36: 10G SFP+ | D36: 10000 | E36: up | F36: Backhaul to DL-DC-009 | G36: SFP-10G-LR
A37: MH-DC-001-PE-T4-02 | B37: xe-0/0/3 | C37: 10G SFP+ | D37: 10000 | E37: up | F37: Backhaul to UP-DC-006 | G37: SFP-10G-LR
A38: MH-DC-001-PE-T4-02 | B38: xe-0/0/4 | C38: 10G SFP+ | D38: 10000 | E38: up | F38: Backhaul to BR-DC-019 | G38: SFP-10G-LR
A39: MH-DC-001-PE-T4-02 | B39: xe-0/0/5 | C39: 10G SFP+ | D39: 10000 | E39: up | F39: Backhaul to TS-DC-023 | G39: SFP-10G-LR
A40: MH-DC-001-PE-T4-02 | B40: xe-0/0/6 | C40: 10G SFP+ | D40: 10000 | E40: up | F40: Uplink to MH-DC-001-AGG-R01 | G40: SFP-10G-LR
A41: MH-DC-001-PE-T4-02 | B41: xe-0/0/7 | C41: 10G SFP+ | D41: 10000 | E41: up | F41: Uplink to MH-DC-001-AGG-R02 | G41: SFP-10G-LR
A42: MH-DC-001-PE-T4-02 | B42: xe-0/0/8 | C42: 10G SFP+ | D42: 10000 | E42: admin-down
A43: MH-DC-001-PE-T4-02 | B43: xe-0/0/9 | C43: 10G SFP+ | D43: 10000 | E43: admin-down
A44: MH-DC-001-PE-T4-02 | B44: xe-0/0/10 | C44: 10G SFP+ | D44: 10000 | E44: admin-down
A45: MH-DC-001-PE-T4-02 | B45: xe-0/0/11 | C45: 10G SFP+ | D45: 10000 | E45: admin-down
...

Sheet Links
A1: link_id * | B1: a_device_id * | C1: a_if_name * | D1: z_device_id * | E1: z_if_name * | F1: role * | G1: protocol | H1: capacity_mbps * | I1: cable_id | J1: strand | K1: a_patch_port | L1: z_patch_port | M1: carrier_circuit_id
A2: LNK-00001 | B2: MH-DC-001-PE-T4-01 | C2: et-0/1/0 | D2: MH-DC-001-PE-T4-02 | E2: et-0/1/0 | F2: Fabric | G2: LLDP | H2: 100000 | I2: MH-DC-001-CBL-0001 | J2: Red | K2: ODF-2/P24 | L2: ODF-2/P15
A3: LNK-00002 | B3: MH-DC-001-PE-T4-01 | C3: et-0/1/0 | D3: MH-DC-001-PE-T4-02 | E3: et-0/1/0 | F3: Fabric | G3: OSPF | H3: 100000
A4: LNK-00003 | B4: MH-DC-001-PE-T4-01 | C4: et-0/1/0 | D4: MH-DC-001-PE-T4-02 | E4: et-0/1/0 | F4: Fabric | G4: ISIS | H4: 100000
A5: LNK-00004 | B5: MH-DC-001-PE-T4-01 | C5: et-0/1/0 | D5: MH-DC-001-PE-T4-02 | E5: et-0/1/0 | F5: Fabric | G5: BGP | H5: 100000
A6: LNK-00005 | B6: MH-DC-001-PE-T4-01 | C6: et-0/1/0 | D6: MH-DC-001-PE-T4-02 | E6: et-0/1/0 | F6: Fabric | G6: LSP | H6: 100000
A7: LNK-00006 | B7: MH-DC-001-PE-T4-01 | C7: et-0/1/1 | D7: MH-DC-001-PE-T4-03 | E7: Hu0/0/1/0 | F7: Fabric | G7: LLDP | H7: 100000 | I7: MH-DC-001-CBL-0002 | J7: Yellow | K7: ODF-4/P13 | L7: ODF-2/P12
A8: LNK-00007 | B8: MH-DC-001-PE-T4-01 | C8: et-0/1/1 | D8: MH-DC-001-PE-T4-03 | E8: Hu0/0/1/0 | F8: Fabric | G8: OSPF | H8: 100000
A9: LNK-00008 | B9: MH-DC-001-PE-T4-01 | C9: et-0/1/1 | D9: MH-DC-001-PE-T4-03 | E9: Hu0/0/1/0 | F9: Fabric | G9: ISIS | H9: 100000
A10: LNK-00009 | B10: MH-DC-001-PE-T4-01 | C10: et-0/1/1 | D10: MH-DC-001-PE-T4-03 | E10: Hu0/0/1/0 | F10: Fabric | G10: BGP | H10: 100000
A11: LNK-00010 | B11: MH-DC-001-PE-T4-01 | C11: et-0/1/1 | D11: MH-DC-001-PE-T4-03 | E11: Hu0/0/1/0 | F11: Fabric | G11: LSP | H11: 100000
A12: LNK-00011 | B12: MH-DC-001-PE-T4-01 | C12: et-0/1/2 | D12: MH-DC-001-PE-T4-04 | E12: Hu0/0/1/0 | F12: Fabric | G12: LLDP | H12: 100000 | I12: MH-DC-001-CBL-0003 | J12: Rose | K12: ODF-2/P17 | L12: ODF-2/P19
A13: LNK-00012 | B13: MH-DC-001-PE-T4-01 | C13: et-0/1/2 | D13: MH-DC-001-PE-T4-04 | E13: Hu0/0/1/0 | F13: Fabric | G13: OSPF | H13: 100000
A14: LNK-00013 | B14: MH-DC-001-PE-T4-01 | C14: et-0/1/2 | D14: MH-DC-001-PE-T4-04 | E14: Hu0/0/1/0 | F14: Fabric | G14: ISIS | H14: 100000
A15: LNK-00014 | B15: MH-DC-001-PE-T4-01 | C15: et-0/1/2 | D15: MH-DC-001-PE-T4-04 | E15: Hu0/0/1/0 | F15: Fabric | G15: BGP | H15: 100000
A16: LNK-00015 | B16: MH-DC-001-PE-T4-01 | C16: et-0/1/2 | D16: MH-DC-001-PE-T4-04 | E16: Hu0/0/1/0 | F16: Fabric | G16: LSP | H16: 100000
A17: LNK-00016 | B17: MH-DC-001-PE-T4-02 | C17: et-0/1/1 | D17: MH-DC-001-PE-T4-03 | E17: Hu0/0/1/1 | F17: Fabric | G17: LLDP | H17: 100000 | I17: MH-DC-001-CBL-0004 | J17: Brown | K17: ODF-3/P24 | L17: ODF-2/P20
A18: LNK-00017 | B18: MH-DC-001-PE-T4-02 | C18: et-0/1/1 | D18: MH-DC-001-PE-T4-03 | E18: Hu0/0/1/1 | F18: Fabric | G18: OSPF | H18: 100000
A19: LNK-00018 | B19: MH-DC-001-PE-T4-02 | C19: et-0/1/1 | D19: MH-DC-001-PE-T4-03 | E19: Hu0/0/1/1 | F19: Fabric | G19: ISIS | H19: 100000
A20: LNK-00019 | B20: MH-DC-001-PE-T4-02 | C20: et-0/1/1 | D20: MH-DC-001-PE-T4-03 | E20: Hu0/0/1/1 | F20: Fabric | G20: BGP | H20: 100000
A21: LNK-00020 | B21: MH-DC-001-PE-T4-02 | C21: et-0/1/1 | D21: MH-DC-001-PE-T4-03 | E21: Hu0/0/1/1 | F21: Fabric | G21: LSP | H21: 100000
A22: LNK-00021 | B22: MH-DC-001-PE-T4-02 | C22: et-0/1/2 | D22: MH-DC-001-PE-T4-04 | E22: Hu0/0/1/1 | F22: Fabric | G22: LLDP | H22: 100000 | I22: MH-DC-001-CBL-0005 | J22: Black | K22: ODF-3/P2 | L22: ODF-3/P12
A23: LNK-00022 | B23: MH-DC-001-PE-T4-02 | C23: et-0/1/2 | D23: MH-DC-001-PE-T4-04 | E23: Hu0/0/1/1 | F23: Fabric | G23: OSPF | H23: 100000
A24: LNK-00023 | B24: MH-DC-001-PE-T4-02 | C24: et-0/1/2 | D24: MH-DC-001-PE-T4-04 | E24: Hu0/0/1/1 | F24: Fabric | G24: ISIS | H24: 100000
A25: LNK-00024 | B25: MH-DC-001-PE-T4-02 | C25: et-0/1/2 | D25: MH-DC-001-PE-T4-04 | E25: Hu0/0/1/1 | F25: Fabric | G25: BGP | H25: 100000
A26: LNK-00025 | B26: MH-DC-001-PE-T4-02 | C26: et-0/1/2 | D26: MH-DC-001-PE-T4-04 | E26: Hu0/0/1/1 | F26: Fabric | G26: LSP | H26: 100000
A27: LNK-00026 | B27: MH-DC-001-PE-T4-03 | C27: Hu0/0/1/2 | D27: MH-DC-001-PE-T4-04 | E27: Hu0/0/1/2 | F27: Fabric | G27: LLDP | H27: 100000 | I27: MH-DC-001-CBL-0006 | J27: Black | K27: ODF-3/P6 | L27: ODF-4/P2
A28: LNK-00027 | B28: MH-DC-001-PE-T4-03 | C28: Hu0/0/1/2 | D28: MH-DC-001-PE-T4-04 | E28: Hu0/0/1/2 | F28: Fabric | G28: OSPF | H28: 100000
A29: LNK-00028 | B29: MH-DC-001-PE-T4-03 | C29: Hu0/0/1/2 | D29: MH-DC-001-PE-T4-04 | E29: Hu0/0/1/2 | F29: Fabric | G29: ISIS | H29: 100000
A30: LNK-00029 | B30: MH-DC-001-PE-T4-03 | C30: Hu0/0/1/2 | D30: MH-DC-001-PE-T4-04 | E30: Hu0/0/1/2 | F30: Fabric | G30: BGP | H30: 100000
A31: LNK-00030 | B31: MH-DC-001-PE-T4-03 | C31: Hu0/0/1/2 | D31: MH-DC-001-PE-T4-04 | E31: Hu0/0/1/2 | F31: Fabric | G31: LSP | H31: 100000
