Workbook
Name L_business_model: Lookups!$A$2:$A$6
Name L_site_status: Lookups!$B$2:$B$5
Name L_tier: Lookups!$C$2:$C$4
Name L_site_category: Lookups!$D$2:$D$4
Name L_redundancy: Lookups!$E$2:$E$4
Name L_room_type: Lookups!$F$2:$F$9
Name L_containment: Lookups!$G$2:$G$4
Name L_cooling_method: Lookups!$H$2:$H$4
Name L_rack_role: Lookups!$I$2:$I$10
Name L_owner: Lookups!$J$2:$J$3
Name L_density: Lookups!$K$2:$K$3
Name L_yes_no: Lookups!$L$2:$L$3
Name L_feed_type: Lookups!$M$2:$M$3
Name L_feed_role: Lookups!$N$2:$N$3
Name L_plant_kind: Lookups!$O$2:$O$3
Name L_test_result: Lookups!$P$2:$P$3
Name L_cooling_type: Lookups!$Q$2:$Q$4
Name L_sensor_kind: Lookups!$R$2:$R$4
Name L_device_role: Lookups!$S$2:$S$10
Name L_layer: Lookups!$T$2:$T$5
Name L_lifecycle: Lookups!$U$2:$U$5
Name L_if_admin: Lookups!$V$2:$V$4
Name L_link_role: Lookups!$W$2:$W$6
Name L_protocol: Lookups!$X$2:$X$6
Name L_gpu_model: Lookups!$Y$2:$Y$9
Name L_gpu_vendor: Lookups!$Z$2:$Z$3
Name L_scheduler: Lookups!$AA$2:$AA$3
Name L_air_liquid: Lookups!$AB$2:$AB$3
Name L_service_type: Lookups!$AC$2:$AC$24
Name L_service_unit: Lookups!$AD$2:$AD$9
Name L_collector_protocol: Lookups!$AE$2:$AE$8
Name L_collector_domain: Lookups!$AF$2:$AF$5

Sheet README
A1: DCO · Datacenter inventory import template
A2: Version 1.0 · 12-Oct-2026 · matches the DCO data model (app/src/api/types.ts)
A4: What this workbook is for
A5: Use it to collect everything the DCO platform needs to know about a customer's datacenters BEFORE monitoring is switched on: sites, floors, rooms, racks, power and cooling plant, sensors, every racked device, its ports and cables, GPU clusters, customers and the services they buy, and the monitoring sources.
A6: The two example sites (RackBank Indore DC1 = colocation with AI cages, RackBank Chennai AI-1 = GPU cloud) are ILLUSTRATIVE sample data. Replace them, or keep them as a reference and delete before import.
A8: How to fill it
A9: 1. Fill the sheets in tab order. A sheet can only point at IDs that exist in the sheets before it (Sites → Floors → Rooms → Racks → … → Services).
A10: 2. Row 1 holds the import keys. Don't rename, reorder or delete columns. Hover over a header for its meaning; the Field_Dictionary sheet lists every field.
A11: 3. Header colours: dark blue = required · amber = required in some cases (see the note) · grey = optional · green = calculated by a formula (don't type it).
A12: 4. Columns with a fixed set of values have a dropdown (from the Lookups sheet). Dates use YYYY-MM-DD. Numbers are plain, with no units in the cell. Lists inside a cell use ";".
A13: 5. IDs must be unique and stable: the system keys every alarm, incident and revenue figure on them. Recommended: site XX-DC-NNN, then <site>-<object> (MP-DC-001-A01).
A14: 6. Check the Summary sheet when you finish. Every count must match what the customer expects, and the checks column must say OK.
... A24: Sheet order and the system object each one fills
A25: Sheet | B25: System object | C25: What goes in it | D25: Example rows
A26: Sites | B26: Datacenter + Location | C26: One row per datacenter. | D26: 2
A27: Floors | B27: Datacenter.floors[] | C27: One row per floor. | D27: 4
A28: Rooms | B28: Datacenter.floors[].rooms[] | C28: One row per room / hall. | D28: 8
A29: Racks | B29: Rack | C29: One row per cabinet, including tenant cabinets and AI cages. | D29: 20
A30: Power_Feeds | B30: Datacenter.power.feeds[] (PowerFeed) | C30: Utility, DG and DC-plant feeds. | D30: 6
A31: UPS | B31: Datacenter.power.ups[] (UpsUnit) | C31: One row per UPS module or system. | D31: 7
A32: Generators | B32: Datacenter.power.dg | C32: Diesel generator sets. | D32: 4
A33: DC_Plant | B33: Datacenter.power.battery + rectifier | C33: 48 V DC plant: rectifiers and battery banks. | D33: 4
A34: Cooling_Units | B34: Datacenter.cooling.units[] (CoolingUnit) | C34: CRAH, CRAC and CDU units. | D34: 12
A35: CDUs | B35: Cdu | C35: Liquid-cooling loops (only for liquid-cooled racks). | D35: 3
A36: Sensors | B36: Datacenter.cooling.sensors[] (EnvSensor) | C36: Environment sensors. | D36: 14
A37: Devices | B37: NetworkElement | C37: Every racked device: network, servers, storage, GPU nodes, and opaque tenant gear blocks. | D37: 43
... A45: Collectors | B45: Datacenter.collectors[] | C45: Monitoring sources the system will receive live data from. | D45: 6
A46: Summary | B46: — | C46: Counts per site and the reconciliation checks (formulas).
A47: Field_Dictionary | B47: — | C47: Every column: required, type, allowed values, the system field it maps to.
A48: Lookups | B48: — | C48: Allowed values behind the dropdowns.

Sheet Summary
A1: Summary and reconciliation checks
A2: Every figure is a formula over the data sheets. Check it with the customer: these are the numbers the platform will show.
A4: Measure | B4: =IF('Sites'!A2="","(site 1)",'Sites'!A2) | C4: =IF('Sites'!A3="","(site 2)",'Sites'!A3) | D4: =IF('Sites'!A4="","(site 3)",'Sites'!A4) | E4: =IF('Sites'!A5="","(site 4)",'Sites'!A5) | F4: =IF('Sites'!A6="","(site 5)",'Sites'!A6) | G4: =IF('Sites'!A7="","(site 6)",'Sites'!A7) | H4: Total
A5: Floors | B5: =IF('Sites'!$A$2="","",COUNTIF('Floors'!$A$2:$A$2000,B$4)) | C5: =IF('Sites'!$A$3="","",COUNTIF('Floors'!$A$2:$A$2000,C$4)) | D5: =IF('Sites'!$A$4="","",COUNTIF('Floors'!$A$2:$A$2000,D$4)) | E5: =IF('Sites'!$A$5="","",COUNTIF('Floors'!$A$2:$A$2000,E$4)) | F5: =IF('Sites'!$A$6="","",COUNTIF('Floors'!$A$2:$A$2000,F$4)) | G5: =IF('Sites'!$A$7="","",COUNTIF('Floors'!$A$2:$A$2000,G$4)) | H5: =SUM(B5:G5)
A6: Rooms | B6: =IF('Sites'!$A$2="","",COUNTIF('Rooms'!$A$2:$A$2000,B$4)) | C6: =IF('Sites'!$A$3="","",COUNTIF('Rooms'!$A$2:$A$2000,C$4)) | D6: =IF('Sites'!$A$4="","",COUNTIF('Rooms'!$A$2:$A$2000,D$4)) | E6: =IF('Sites'!$A$5="","",COUNTIF('Rooms'!$A$2:$A$2000,E$4)) | F6: =IF('Sites'!$A$6="","",COUNTIF('Rooms'!$A$2:$A$2000,F$4)) | G6: =IF('Sites'!$A$7="","",COUNTIF('Rooms'!$A$2:$A$2000,G$4)) | H6: =SUM(B6:G6)
A7: Racks | B7: =IF('Sites'!$A$2="","",COUNTIF('Racks'!$B$2:$B$2000,B$4)) | C7: =IF('Sites'!$A$3="","",COUNTIF('Racks'!$B$2:$B$2000,C$4)) | D7: =IF('Sites'!$A$4="","",COUNTIF('Racks'!$B$2:$B$2000,D$4)) | E7: =IF('Sites'!$A$5="","",COUNTIF('Racks'!$B$2:$B$2000,E$4)) | F7: =IF('Sites'!$A$6="","",COUNTIF('Racks'!$B$2:$B$2000,F$4)) | G7: =IF('Sites'!$A$7="","",COUNTIF('Racks'!$B$2:$B$2000,G$4)) | H7: =SUM(B7:G7)
A8: of which tenant cabinets | B8: =IF('Sites'!$A$2="","",COUNTIFS('Racks'!$B$2:$B$2000,B$4,'Racks'!$J$2:$J$2000,"tenant")) | C8: =IF('Sites'!$A$3="","",COUNTIFS('Racks'!$B$2:$B$2000,C$4,'Racks'!$J$2:$J$2000,"tenant")) | D8: =IF('Sites'!$A$4="","",COUNTIFS('Racks'!$B$2:$B$2000,D$4,'Racks'!$J$2:$J$2000,"tenant")) | E8: =IF('Sites'!$A$5="","",COUNTIFS('Racks'!$B$2:$B$2000,E$4,'Racks'!$J$2:$J$2000,"tenant")) | F8: =IF('Sites'!$A$6="","",COUNTIFS('Racks'!$B$2:$B$2000,F$4,'Racks'!$J$2:$J$2000,"tenant")) | G8: =IF('Sites'!$A$7="","",COUNTIFS('Racks'!$B$2:$B$2000,G$4,'Racks'!$J$2:$J$2000,"tenant")) | H8: =SUM(B8:G8)
A9: of which AI / high-density | B9: =IF('Sites'!$A$2="","",COUNTIFS('Racks'!$B$2:$B$2000,B$4,'Racks'!$M$2:$M$2000,"ai")) | C9: =IF('Sites'!$A$3="","",COUNTIFS('Racks'!$B$2:$B$2000,C$4,'Racks'!$M$2:$M$2000,"ai")) | D9: =IF('Sites'!$A$4="","",COUNTIFS('Racks'!$B$2:$B$2000,D$4,'Racks'!$M$2:$M$2000,"ai")) | E9: =IF('Sites'!$A$5="","",COUNTIFS('Racks'!$B$2:$B$2000,E$4,'Racks'!$M$2:$M$2000,"ai")) | F9: =IF('Sites'!$A$6="","",COUNTIFS('Racks'!$B$2:$B$2000,F$4,'Racks'!$M$2:$M$2000,"ai")) | G9: =IF('Sites'!$A$7="","",COUNTIFS('Racks'!$B$2:$B$2000,G$4,'Racks'!$M$2:$M$2000,"ai")) | H9: =SUM(B9:G9)
A10: Rack power budget (kW) | B10: =IF('Sites'!$A$2="","",SUMIF('Racks'!$B$2:$B$2000,B$4,'Racks'!$I$2:$I$2000)) | C10: =IF('Sites'!$A$3="","",SUMIF('Racks'!$B$2:$B$2000,C$4,'Racks'!$I$2:$I$2000)) | D10: =IF('Sites'!$A$4="","",SUMIF('Racks'!$B$2:$B$2000,D$4,'Racks'!$I$2:$I$2000)) | E10: =IF('Sites'!$A$5="","",SUMIF('Racks'!$B$2:$B$2000,E$4,'Racks'!$I$2:$I$2000)) | F10: =IF('Sites'!$A$6="","",SUMIF('Racks'!$B$2:$B$2000,F$4,'Racks'!$I$2:$I$2000)) | G10: =IF('Sites'!$A$7="","",SUMIF('Racks'!$B$2:$B$2000,G$4,'Racks'!$I$2:$I$2000)) | H10: =SUM(B10:G10)
A11: Site IT capacity (kW) | B11: =IF('Sites'!$A$2="","",SUMIF('Sites'!$A$2:$A$2000,B$4,'Sites'!$O$2:$O$2000)) | C11: =IF('Sites'!$A$3="","",SUMIF('Sites'!$A$2:$A$2000,C$4,'Sites'!$O$2:$O$2000)) | D11: =IF('Sites'!$A$4="","",SUMIF('Sites'!$A$2:$A$2000,D$4,'Sites'!$O$2:$O$2000)) | E11: =IF('Sites'!$A$5="","",SUMIF('Sites'!$A$2:$A$2000,E$4,'Sites'!$O$2:$O$2000)) | F11: =IF('Sites'!$A$6="","",SUMIF('Sites'!$A$2:$A$2000,F$4,'Sites'!$O$2:$O$2000)) | G11: =IF('Sites'!$A$7="","",SUMIF('Sites'!$A$2:$A$2000,G$4,'Sites'!$O$2:$O$2000)) | H11: =SUM(B11:G11)
A12: Devices (all) | B12: =IF('Sites'!$A$2="","",COUNTIFS('Devices'!$B$2:$B$2000,B$4)) | C12: =IF('Sites'!$A$3="","",COUNTIFS('Devices'!$B$2:$B$2000,C$4)) | D12: =IF('Sites'!$A$4="","",COUNTIFS('Devices'!$B$2:$B$2000,D$4)) | E12: =IF('Sites'!$A$5="","",COUNTIFS('Devices'!$B$2:$B$2000,E$4)) | F12: =IF('Sites'!$A$6="","",COUNTIFS('Devices'!$B$2:$B$2000,F$4)) | G12: =IF('Sites'!$A$7="","",COUNTIFS('Devices'!$B$2:$B$2000,G$4)) | H12: =SUM(B12:G12)
A13: operator devices | B13: =IF('Sites'!$A$2="","",COUNTIFS('Devices'!$B$2:$B$2000,B$4,'Devices'!$P$2:$P$2000,"operator")) | C13: =IF('Sites'!$A$3="","",COUNTIFS('Devices'!$B$2:$B$2000,C$4,'Devices'!$P$2:$P$2000,"operator")) | D13: =IF('Sites'!$A$4="","",COUNTIFS('Devices'!$B$2:$B$2000,D$4,'Devices'!$P$2:$P$2000,"operator")) | E13: =IF('Sites'!$A$5="","",COUNTIFS('Devices'!$B$2:$B$2000,E$4,'Devices'!$P$2:$P$2000,"operator")) | F13: =IF('Sites'!$A$6="","",COUNTIFS('Devices'!$B$2:$B$2000,F$4,'Devices'!$P$2:$P$2000,"operator")) | G13: =IF('Sites'!$A$7="","",COUNTIFS('Devices'!$B$2:$B$2000,G$4,'Devices'!$P$2:$P$2000,"operator")) | H13: =SUM(B13:G13)
A14: tenant gear blocks | B14: =IF('Sites'!$A$2="","",COUNTIFS('Devices'!$B$2:$B$2000,B$4,'Devices'!$P$2:$P$2000,"tenant")) | C14: =IF('Sites'!$A$3="","",COUNTIFS('Devices'!$B$2:$B$2000,C$4,'Devices'!$P$2:$P$2000,"tenant")) | D14: =IF('Sites'!$A$4="","",COUNTIFS('Devices'!$B$2:$B$2000,D$4,'Devices'!$P$2:$P$2000,"tenant")) | E14: =IF('Sites'!$A$5="","",COUNTIFS('Devices'!$B$2:$B$2000,E$4,'Devices'!$P$2:$P$2000,"tenant")) | F14: =IF('Sites'!$A$6="","",COUNTIFS('Devices'!$B$2:$B$2000,F$4,'Devices'!$P$2:$P$2000,"tenant")) | G14: =IF('Sites'!$A$7="","",COUNTIFS('Devices'!$B$2:$B$2000,G$4,'Devices'!$P$2:$P$2000,"tenant")) | H14: =SUM(B14:G14)
A15: GPU nodes | B15: =IF('Sites'!$A$2="","",COUNTIFS('Devices'!$B$2:$B$2000,B$4,'Devices'!$D$2:$D$2000,"GPU")) | C15: =IF('Sites'!$A$3="","",COUNTIFS('Devices'!$B$2:$B$2000,C$4,'Devices'!$D$2:$D$2000,"GPU")) | D15: =IF('Sites'!$A$4="","",COUNTIFS('Devices'!$B$2:$B$2000,D$4,'Devices'!$D$2:$D$2000,"GPU")) | E15: =IF('Sites'!$A$5="","",COUNTIFS('Devices'!$B$2:$B$2000,E$4,'Devices'!$D$2:$D$2000,"GPU")) | F15: =IF('Sites'!$A$6="","",COUNTIFS('Devices'!$B$2:$B$2000,F$4,'Devices'!$D$2:$D$2000,"GPU")) | G15: =IF('Sites'!$A$7="","",COUNTIFS('Devices'!$B$2:$B$2000,G$4,'Devices'!$D$2:$D$2000,"GPU")) | H15: =SUM(B15:G15)
A16: network (routers, firewalls, switches) | B16: =IF('Sites'!$A$2="","",COUNTIFS('Devices'!$B$2:$B$2000,B$4,'Devices'!$D$2:$D$2000,"Router")+COUNTIFS('Devices'!$B$2:$B$2000,B$4,'Devices'!$D$2:$D$2000,"Firewall")+COUNTIFS('Devices'!$B$2:$B$2000,B$4,'Devices'!$D$2:$D$2000,"Switch")) | C16: =IF('Sites'!$A$3="","",COUNTIFS('Devices'!$B$2:$B$2000,C$4,'Devices'!$D$2:$D$2000,"Router")+COUNTIFS('Devices'!$B$2:$B$2000,C$4,'Devices'!$D$2:$D$2000,"Firewall")+COUNTIFS('Devices'!$B$2:$B$2000,C$4,'Devices'!$D$2:$D$2000,"Switch")) | D16: =IF('Sites'!$A$4="","",COUNTIFS('Devices'!$B$2:$B$2000,D$4,'Devices'!$D$2:$D$2000,"Router")+COUNTIFS('Devices'!$B$2:$B$2000,D$4,'Devices'!$D$2:$D$2000,"Firewall")+COUNTIFS('Devices'!$B$2:$B$2000,D$4,'Devices'!$D$2:$D$2000,"Switch")) | E16: =IF('Sites'!$A$5="","",COUNTIFS('Devices'!$B$2:$B$2000,E$4,'Devices'!$D$2:$D$2000,"Router")+COUNTIFS('Devices'!$B$2:$B$2000,E$4,'Devices'!$D$2:$D$2000,"Firewall")+COUNTIFS('Devices'!$B$2:$B$2000,E$4,'Devices'!$D$2:$D$2000,"Switch")) | F16: =IF('Sites'!$A$6="","",COUNTIFS('Devices'!$B$2:$B$2000,F$4,'Devices'!$D$2:$D$2000,"Router")+COUNTIFS('Devices'!$B$2:$B$2000,F$4,'Devices'!$D$2:$D$2000,"Firewall")+COUNTIFS('Devices'!$B$2:$B$2000,F$4,'Devices'!$D$2:$D$2000,"Switch")) | G16: =IF('Sites'!$A$7="","",COUNTIFS('Devices'!$B$2:$B$2000,G$4,'Devices'!$D$2:$D$2000,"Router")+COUNTIFS('Devices'!$B$2:$B$2000,G$4,'Devices'!$D$2:$D$2000,"Firewall")+COUNTIFS('Devices'!$B$2:$B$2000,G$4,'Devices'!$D$2:$D$2000,"Switch")) | H16: =SUM(B16:G16)
A17: UPS units | B17: =IF('Sites'!$A$2="","",COUNTIF('UPS'!$B$2:$B$2000,B$4)) | C17: =IF('Sites'!$A$3="","",COUNTIF('UPS'!$B$2:$B$2000,C$4)) | D17: =IF('Sites'!$A$4="","",COUNTIF('UPS'!$B$2:$B$2000,D$4)) | E17: =IF('Sites'!$A$5="","",COUNTIF('UPS'!$B$2:$B$2000,E$4)) | F17: =IF('Sites'!$A$6="","",COUNTIF('UPS'!$B$2:$B$2000,F$4)) | G17: =IF('Sites'!$A$7="","",COUNTIF('UPS'!$B$2:$B$2000,G$4)) | H17: =SUM(B17:G17)
A18: UPS capacity (kW) | B18: =IF('Sites'!$A$2="","",SUMIF('UPS'!$B$2:$B$2000,B$4,'UPS'!$H$2:$H$2000)) | C18: =IF('Sites'!$A$3="","",SUMIF('UPS'!$B$2:$B$2000,C$4,'UPS'!$H$2:$H$2000)) | D18: =IF('Sites'!$A$4="","",SUMIF('UPS'!$B$2:$B$2000,D$4,'UPS'!$H$2:$H$2000)) | E18: =IF('Sites'!$A$5="","",SUMIF('UPS'!$B$2:$B$2000,E$4,'UPS'!$H$2:$H$2000)) | F18: =IF('Sites'!$A$6="","",SUMIF('UPS'!$B$2:$B$2000,F$4,'UPS'!$H$2:$H$2000)) | G18: =IF('Sites'!$A$7="","",SUMIF('UPS'!$B$2:$B$2000,G$4,'UPS'!$H$2:$H$2000)) | H18: =SUM(B18:G18)
A19: Generators | B19: =IF('Sites'!$A$2="","",COUNTIF('Generators'!$B$2:$B$2000,B$4)) | C19: =IF('Sites'!$A$3="","",COUNTIF('Generators'!$B$2:$B$2000,C$4)) | D19: =IF('Sites'!$A$4="","",COUNTIF('Generators'!$B$2:$B$2000,D$4)) | E19: =IF('Sites'!$A$5="","",COUNTIF('Generators'!$B$2:$B$2000,E$4)) | F19: =IF('Sites'!$A$6="","",COUNTIF('Generators'!$B$2:$B$2000,F$4)) | G19: =IF('Sites'!$A$7="","",COUNTIF('Generators'!$B$2:$B$2000,G$4)) | H19: =SUM(B19:G19)
A20: Cooling units | B20: =IF('Sites'!$A$2="","",COUNTIF('Cooling_Units'!$B$2:$B$2000,B$4)) | C20: =IF('Sites'!$A$3="","",COUNTIF('Cooling_Units'!$B$2:$B$2000,C$4)) | D20: =IF('Sites'!$A$4="","",COUNTIF('Cooling_Units'!$B$2:$B$2000,D$4)) | E20: =IF('Sites'!$A$5="","",COUNTIF('Cooling_Units'!$B$2:$B$2000,E$4)) | F20: =IF('Sites'!$A$6="","",COUNTIF('Cooling_Units'!$B$2:$B$2000,F$4)) | G20: =IF('Sites'!$A$7="","",COUNTIF('Cooling_Units'!$B$2:$B$2000,G$4)) | H20: =SUM(B20:G20)
A21: Cooling unit capacity (kW) | B21: =IF('Sites'!$A$2="","",SUMIF('Cooling_Units'!$B$2:$B$2000,B$4,'Cooling_Units'!$H$2:$H$2000)) | C21: =IF('Sites'!$A$3="","",SUMIF('Cooling_Units'!$B$2:$B$2000,C$4,'Cooling_Units'!$H$2:$H$2000)) | D21: =IF('Sites'!$A$4="","",SUMIF('Cooling_Units'!$B$2:$B$2000,D$4,'Cooling_Units'!$H$2:$H$2000)) | E21: =IF('Sites'!$A$5="","",SUMIF('Cooling_Units'!$B$2:$B$2000,E$4,'Cooling_Units'!$H$2:$H$2000)) | F21: =IF('Sites'!$A$6="","",SUMIF('Cooling_Units'!$B$2:$B$2000,F$4,'Cooling_Units'!$H$2:$H$2000)) | G21: =IF('Sites'!$A$7="","",SUMIF('Cooling_Units'!$B$2:$B$2000,G$4,'Cooling_Units'!$H$2:$H$2000)) | H21: =SUM(B21:G21)
A22: Sensors | B22: =IF('Sites'!$A$2="","",COUNTIF('Sensors'!$B$2:$B$2000,B$4)) | C22: =IF('Sites'!$A$3="","",COUNTIF('Sensors'!$B$2:$B$2000,C$4)) | D22: =IF('Sites'!$A$4="","",COUNTIF('Sensors'!$B$2:$B$2000,D$4)) | E22: =IF('Sites'!$A$5="","",COUNTIF('Sensors'!$B$2:$B$2000,E$4)) | F22: =IF('Sites'!$A$6="","",COUNTIF('Sensors'!$B$2:$B$2000,F$4)) | G22: =IF('Sites'!$A$7="","",COUNTIF('Sensors'!$B$2:$B$2000,G$4)) | H22: =SUM(B22:G22)
A23: Collectors | B23: =IF('Sites'!$A$2="","",COUNTIF('Collectors'!$B$2:$B$2000,B$4)) | C23: =IF('Sites'!$A$3="","",COUNTIF('Collectors'!$B$2:$B$2000,C$4)) | D23: =IF('Sites'!$A$4="","",COUNTIF('Collectors'!$B$2:$B$2000,D$4)) | E23: =IF('Sites'!$A$5="","",COUNTIF('Collectors'!$B$2:$B$2000,E$4)) | F23: =IF('Sites'!$A$6="","",COUNTIF('Collectors'!$B$2:$B$2000,F$4)) | G23: =IF('Sites'!$A$7="","",COUNTIF('Collectors'!$B$2:$B$2000,G$4)) | H23: =SUM(B23:G23)
A24: Services | B24: =IF('Sites'!$A$2="","",COUNTIF('Services'!$D$2:$D$2000,B$4)) | C24: =IF('Sites'!$A$3="","",COUNTIF('Services'!$D$2:$D$2000,C$4)) | D24: =IF('Sites'!$A$4="","",COUNTIF('Services'!$D$2:$D$2000,D$4)) | E24: =IF('Sites'!$A$5="","",COUNTIF('Services'!$D$2:$D$2000,E$4)) | F24: =IF('Sites'!$A$6="","",COUNTIF('Services'!$D$2:$D$2000,F$4)) | G24: =IF('Sites'!$A$7="","",COUNTIF('Services'!$D$2:$D$2000,G$4)) | H24: =SUM(B24:G24)
A25: Services monthly revenue (₹) | B25: =IF('Sites'!$A$2="","",SUMIF('Services'!$D$2:$D$2000,B$4,'Services'!$M$2:$M$2000)) | C25: =IF('Sites'!$A$3="","",SUMIF('Services'!$D$2:$D$2000,C$4,'Services'!$M$2:$M$2000)) | D25: =IF('Sites'!$A$4="","",SUMIF('Services'!$D$2:$D$2000,D$4,'Services'!$M$2:$M$2000)) | E25: =IF('Sites'!$A$5="","",SUMIF('Services'!$D$2:$D$2000,E$4,'Services'!$M$2:$M$2000)) | F25: =IF('Sites'!$A$6="","",SUMIF('Services'!$D$2:$D$2000,F$4,'Services'!$M$2:$M$2000)) | G25: =IF('Sites'!$A$7="","",SUMIF('Services'!$D$2:$D$2000,G$4,'Services'!$M$2:$M$2000)) | H25: =SUM(B25:G25)
A28: Checks
A29: Check | B29: Result | C29: Why it matters
A30: Every device sits in a rack that exists | B30: =IF(SUMPRODUCT(--(COUNTIF('Racks'!$A$2:$A$2000,'Devices'!$L$2:$L$44)=0))=0,"OK","FIX: unknown rack_id") | C30: The twin and rack views place devices by rack_id.
A31: No rack is over-filled (used U ≤ height U) | B31: =IF(SUMPRODUCT(--('Racks'!$R$2:$R$21>'Racks'!$H$2:$H$21))=0,"OK","FIX: rack over capacity") | C31: used_u is calculated from Devices.
A32: Device IDs are unique | B32: =IF(SUMPRODUCT(--(COUNTIF('Devices'!$A$2:$A$44,'Devices'!$A$2:$A$44)>1))=0,"OK","FIX: duplicate device_id") | C32: Alarms and incidents key on the device ID.
A33: Operator serial numbers are unique | B33: =IF(SUMPRODUCT(('Devices'!$I$2:$I$44<>"")*(COUNTIF('Devices'!$I$2:$I$44,'Devices'!$I$2:$I$44)>1))=0,"OK","FIX: duplicate serial") | C33: Discovery matches the polled serial against this one.
A34: Tenant racks name a tenant and contracted kW | B34: =IF(COUNTIFS('Racks'!$J$2:$J$21,"tenant",'Racks'!$K$2:$K$21,"")+COUNTIFS('Racks'!$J$2:$J$21,"tenant",'Racks'!$L$2:$L$21,"")=0,"OK","FIX: tenant rack missing data") | C34: Colocation power-over-contract is measured against it.
A35: Liquid racks name a CDU | B35: =IF(COUNTIFS('Racks'!$N$2:$N$21,"Y",'Racks'!$O$2:$O$21,"")=0,"OK","FIX: liquid rack without CDU") | C35: A CDU fault is traced to the racks it feeds.
A36: Rack budget fits site IT capacity | B36: =IF(SUMPRODUCT(--(B10:G10>B11:G11))=0,"OK","CHECK: racks exceed IT capacity") | C36: Power and space views compare the two.
A37: GPU nodes = Devices with role GPU | B37: =IF(COUNTA('GPU_Nodes'!$A$2:$A$2000)=COUNTIF('Devices'!$D$2:$D$2000,"GPU"),"OK","FIX: GPU_Nodes and Devices differ") | C37: Each GPU node needs a rack position and a telemetry record.
A38: Customer revenue = sum of services | B38: =IF(ROUND(SUM('Customers'!$I$2:$I$2000)-SUM('Services'!$M$2:$M$2000),0)=0,"OK","FIX: a service names an unknown customer") | C38: Revenue impact adds up only if every service has a customer.

Sheet Sites
A1: site_id * | B1: site_name * | C1: operator | D1: business_model * | E1: status * | F1: tier * | G1: category * | H1: region * | I1: state * | J1: city * | K1: address * | L1: latitude * | M1: longitude * | N1: commissioned_on | O1: it_capacity_kw * | P1: design_pue | Q1: cooling_capacity_kw * | R1: cooling_redundancy * | S1: timezone
A2: MP-DC-001 | B2: RackBank Indore DC1 | C2: RackBank Datacenters (sample) | D2: colocation | E2: on-air | F2: Tier III | G2: Central | H2: Central | I2: Madhya Pradesh | J2: Indore | K2: Plot 12, Sample IT Park, Indore 452010 (illustrative) | L2: 22.7196 | M2: 75.8577 | N2: 44635 | O2: 1200 | P2: 1.45 | Q2: 1500 | R2: N+1 | S2: Asia/Kolkata
A3: TN-DC-002 | B3: RackBank Chennai AI-1 | C3: RackBank Datacenters (sample) | D3: neocloud | E3: on-air | F3: Tier III | G3: Regional | H3: South | I3: Tamil Nadu | J3: Chennai | K3: Survey 45, Sample Industrial Estate, Chennai 600058 (illustrative) | L3: 13.1143 | M3: 80.1548 | N3: 45677 | O3: 2000 | P3: 1.25 | Q3: 2400 | R3: N+1 | S3: Asia/Kolkata

Sheet Floors
A1: site_id * | B1: floor_id * | C1: floor_name * | D1: level *
A2: MP-DC-001 | B2: MP-DC-001-F0 | C2: Ground | D2: 0
A3: MP-DC-001 | B3: MP-DC-001-F1 | C3: 1st floor | D3: 1
A4: TN-DC-002 | B4: TN-DC-002-F0 | C4: Ground | D4: 0
A5: TN-DC-002 | B5: TN-DC-002-F1 | C5: 1st floor | D5: 1

Sheet Rooms
A1: site_id * | B1: floor_id * | C1: room_id * | D1: room_name * | E1: room_type * | F1: area_sqm | G1: rack_rows | H1: containment | I1: cooling_method
A2: MP-DC-001 | B2: MP-DC-001-F0 | C2: MP-DC-001-MMR | D2: Meet-me room | E2: Meet-me room | F2: 60 | G2: 1 | H2: None | I2: Air
A3: MP-DC-001 | B3: MP-DC-001-F0 | C3: MP-DC-001-PLANT | D3: Plant room | E3: Plant room | F3: 140 | H3: None | I3: Air
A4: MP-DC-001 | B4: MP-DC-001-F1 | C4: MP-DC-001-HALLA | D4: Hall A | E4: Data hall | F4: 420 | G4: 2 | H4: Cold aisle | I4: Air
A5: MP-DC-001 | B5: MP-DC-001-F1 | C5: MP-DC-001-HALLB | D5: Hall B (AI cages) | E5: AI hall | F5: 260 | G5: 2 | H5: Hot aisle | I5: Liquid
A6: TN-DC-002 | B6: TN-DC-002-F0 | C6: TN-DC-002-MMR | D6: Meet-me room | E6: Meet-me room | F6: 50 | G6: 1 | H6: None | I6: Air
A7: TN-DC-002 | B7: TN-DC-002-F0 | C7: TN-DC-002-PLANT | D7: Plant room | E7: Plant room | F7: 180 | H7: None | I7: Air
A8: TN-DC-002 | B8: TN-DC-002-F1 | C8: TN-DC-002-NET | D8: Network & storage room | E8: Network room | F8: 120 | G8: 1 | H8: Cold aisle | I8: Air
A9: TN-DC-002 | B9: TN-DC-002-F1 | C9: TN-DC-002-GPU1 | D9: GPU hall 1 | E9: AI hall | F9: 380 | G9: 2 | H9: Hot aisle | I9: Liquid

Sheet Racks
A1: rack_id * | B1: site_id * | C1: room_id * | D1: rack_name * | E1: row | F1: position | G1: role * | H1: height_u * | I1: power_budget_kw * | J1: owner * | K1: tenant_customer_id | L1: contracted_kw | M1: density | N1: liquid_cooled | O1: cdu_id | P1: pdu_feed_a | Q1: pdu_feed_b | R1: used_u (calc)
A2: MP-DC-001-MMR-R01 | B2: MP-DC-001 | C2: MP-DC-001-MMR | D2: MMR-R01 | E2: M | F2: 1 | G2: Core | H2: 45 | I2: 12 | J2: operator | M2: standard | N2: N | P2: MP-DC-001-AC-1 | Q2: MP-DC-001-AC-2 | R2: =SUMIF('Devices'!$L$2:$L$2000,A2,'Devices'!$N$2:$N$2000)
A3: MP-DC-001-MMR-R02 | B3: MP-DC-001 | C3: MP-DC-001-MMR | D3: MMR-R02 | E3: M | F3: 2 | G3: Meet-me room | H3: 45 | I3: 6 | J3: operator | M3: standard | N3: N | P3: MP-DC-001-AC-1 | Q3: MP-DC-001-AC-2 | R3: =SUMIF('Devices'!$L$2:$L$2000,A3,'Devices'!$N$2:$N$2000)
A4: MP-DC-001-A01 | B4: MP-DC-001 | C4: MP-DC-001-HALLA | D4: A01 | E4: A | F4: 1 | G4: Aggregation | H4: 45 | I4: 10 | J4: operator | M4: standard | N4: N | P4: MP-DC-001-AC-1 | Q4: MP-DC-001-AC-2 | R4: =SUMIF('Devices'!$L$2:$L$2000,A4,'Devices'!$N$2:$N$2000)
A5: MP-DC-001-A02 | B5: MP-DC-001 | C5: MP-DC-001-HALLA | D5: A02 | E5: A | F5: 2 | G5: Tenant | H5: 42 | I5: 8 | J5: tenant | K5: CUST-001 | L5: 6 | M5: standard | N5: N | P5: MP-DC-001-AC-1 | Q5: MP-DC-001-AC-2 | R5: =SUMIF('Devices'!$L$2:$L$2000,A5,'Devices'!$N$2:$N$2000)
A6: MP-DC-001-A03 | B6: MP-DC-001 | C6: MP-DC-001-HALLA | D6: A03 | E6: A | F6: 3 | G6: Tenant | H6: 42 | I6: 8 | J6: tenant | K6: CUST-001 | L6: 6 | M6: standard | N6: N | P6: MP-DC-001-AC-1 | Q6: MP-DC-001-AC-2 | R6: =SUMIF('Devices'!$L$2:$L$2000,A6,'Devices'!$N$2:$N$2000)
A7: MP-DC-001-A04 | B7: MP-DC-001 | C7: MP-DC-001-HALLA | D7: A04 | E7: B | F7: 1 | G7: Tenant | H7: 42 | I7: 10 | J7: tenant | K7: CUST-002 | L7: 8 | M7: standard | N7: N | P7: MP-DC-001-AC-1 | Q7: MP-DC-001-AC-2 | R7: =SUMIF('Devices'!$L$2:$L$2000,A7,'Devices'!$N$2:$N$2000)
A8: MP-DC-001-A05 | B8: MP-DC-001 | C8: MP-DC-001-HALLA | D8: A05 | E8: B | F8: 2 | G8: Tenant | H8: 42 | I8: 8 | J8: tenant | K8: CUST-003 | L8: 6 | M8: standard | N8: N | P8: MP-DC-001-AC-1 | Q8: MP-DC-001-AC-2 | R8: =SUMIF('Devices'!$L$2:$L$2000,A8,'Devices'!$N$2:$N$2000)
A9: MP-DC-001-A06 | B9: MP-DC-001 | C9: MP-DC-001-HALLA | D9: A06 | E9: B | F9: 3 | G9: Tenant | H9: 42 | I9: 8 | J9: tenant | K9: CUST-003 | L9: 6 | M9: standard | N9: N | P9: MP-DC-001-AC-1 | Q9: MP-DC-001-AC-2 | R9: =SUMIF('Devices'!$L$2:$L$2000,A9,'Devices'!$N$2:$N$2000)
A10: MP-DC-001-B01 | B10: MP-DC-001 | C10: MP-DC-001-HALLB | D10: B01 | E10: C | F10: 1 | G10: AI cage | H10: 48 | I10: 50 | J10: tenant | K10: CUST-004 | L10: 40 | M10: ai | N10: Y | O10: MP-DC-001-CDU-01 | P10: MP-DC-001-AC-1 | Q10: MP-DC-001-AC-2 | R10: =SUMIF('Devices'!$L$2:$L$2000,A10,'Devices'!$N$2:$N$2000)
A11: MP-DC-001-B02 | B11: MP-DC-001 | C11: MP-DC-001-HALLB | D11: B02 | E11: C | F11: 2 | G11: AI cage | H11: 48 | I11: 50 | J11: tenant | K11: CUST-004 | L11: 40 | M11: ai | N11: Y | O11: MP-DC-001-CDU-01 | P11: MP-DC-001-AC-1 | Q11: MP-DC-001-AC-2 | R11: =SUMIF('Devices'!$L$2:$L$2000,A11,'Devices'!$N$2:$N$2000)
A12: MP-DC-001-B03 | B12: MP-DC-001 | C12: MP-DC-001-HALLB | D12: B03 | E12: D | F12: 1 | G12: AI cage | H12: 48 | I12: 50 | J12: tenant | K12: CUST-004 | L12: 40 | M12: ai | N12: Y | O12: MP-DC-001-CDU-01 | P12: MP-DC-001-AC-1 | Q12: MP-DC-001-AC-2 | R12: =SUMIF('Devices'!$L$2:$L$2000,A12,'Devices'!$N$2:$N$2000)
A13: MP-DC-001-B04 | B13: MP-DC-001 | C13: MP-DC-001-HALLB | D13: B04 | E13: D | F13: 2 | G13: AI cage | H13: 48 | I13: 50 | J13: tenant | K13: CUST-004 | L13: 40 | M13: ai | N13: Y | O13: MP-DC-001-CDU-01 | P13: MP-DC-001-AC-1 | Q13: MP-DC-001-AC-2 | R13: =SUMIF('Devices'!$L$2:$L$2000,A13,'Devices'!$N$2:$N$2000)
A14: TN-DC-002-MMR-R01 | B14: TN-DC-002 | C14: TN-DC-002-MMR | D14: MMR-R01 | E14: M | F14: 1 | G14: Core | H14: 45 | I14: 12 | J14: operator | M14: standard | N14: N | P14: TN-DC-002-AC-1 | Q14: TN-DC-002-AC-2 | R14: =SUMIF('Devices'!$L$2:$L$2000,A14,'Devices'!$N$2:$N$2000)
A15: TN-DC-002-NET-R01 | B15: TN-DC-002 | C15: TN-DC-002-NET | D15: NET-R01 | E15: N | F15: 1 | G15: Network | H15: 45 | I15: 15 | J15: operator | M15: standard | N15: N | P15: TN-DC-002-AC-1 | Q15: TN-DC-002-AC-2 | R15: =SUMIF('Devices'!$L$2:$L$2000,A15,'Devices'!$N$2:$N$2000)
A16: TN-DC-002-NET-R02 | B16: TN-DC-002 | C16: TN-DC-002-NET | D16: NET-R02 | E16: N | F16: 2 | G16: Network | H16: 45 | I16: 15 | J16: operator | M16: standard | N16: N | P16: TN-DC-002-AC-1 | Q16: TN-DC-002-AC-2 | R16: =SUMIF('Devices'!$L$2:$L$2000,A16,'Devices'!$N$2:$N$2000)
A17: TN-DC-002-STG-R01 | B17: TN-DC-002 | C17: TN-DC-002-NET | D17: STG-R01 | E17: N | F17: 3 | G17: Storage | H17: 45 | I17: 20 | J17: operator | M17: standard | N17: N | P17: TN-DC-002-AC-1 | Q17: TN-DC-002-AC-2 | R17: =SUMIF('Devices'!$L$2:$L$2000,A17,'Devices'!$N$2:$N$2000)
A18: TN-DC-002-GPU-R01 | B18: TN-DC-002 | C18: TN-DC-002-GPU1 | D18: GPU-R01 | E18: G | F18: 1 | G18: GPU | H18: 48 | I18: 60 | J18: operator | M18: ai | N18: Y | O18: TN-DC-002-CDU-01 | P18: TN-DC-002-AC-1 | Q18: TN-DC-002-AC-2 | R18: =SUMIF('Devices'!$L$2:$L$2000,A18,'Devices'!$N$2:$N$2000)
A19: TN-DC-002-GPU-R02 | B19: TN-DC-002 | C19: TN-DC-002-GPU1 | D19: GPU-R02 | E19: G | F19: 2 | G19: GPU | H19: 48 | I19: 60 | J19: operator | M19: ai | N19: Y | O19: TN-DC-002-CDU-01 | P19: TN-DC-002-AC-1 | Q19: TN-DC-002-AC-2 | R19: =SUMIF('Devices'!$L$2:$L$2000,A19,'Devices'!$N$2:$N$2000)
A20: TN-DC-002-GPU-R03 | B20: TN-DC-002 | C20: TN-DC-002-GPU1 | D20: GPU-R03 | E20: H | F20: 1 | G20: GPU | H20: 48 | I20: 60 | J20: operator | M20: ai | N20: Y | O20: TN-DC-002-CDU-02 | P20: TN-DC-002-AC-1 | Q20: TN-DC-002-AC-2 | R20: =SUMIF('Devices'!$L$2:$L$2000,A20,'Devices'!$N$2:$N$2000)
A21: TN-DC-002-GPU-R04 | B21: TN-DC-002 | C21: TN-DC-002-GPU1 | D21: GPU-R04 | E21: H | F21: 2 | G21: GPU | H21: 48 | I21: 60 | J21: operator | M21: ai | N21: Y | O21: TN-DC-002-CDU-02 | P21: TN-DC-002-AC-1 | Q21: TN-DC-002-AC-2 | R21: =SUMIF('Devices'!$L$2:$L$2000,A21,'Devices'!$N$2:$N$2000)

Sheet Power_Feeds
A1: feed_id * | B1: site_id * | C1: type * | D1: source * | E1: rating * | F1: capacity_kw * | G1: normal_role | H1: utility_account
A2: MP-DC-001-AC-1 | B2: MP-DC-001 | C2: AC | D2: Utility feed A (MPPKVVCL 33 kV) | E2: 1250 A · 415 V | F2: 800 | G2: Active | H2: MPW-33KV-0001 (sample)
A3: MP-DC-001-AC-2 | B3: MP-DC-001 | C3: AC | D3: Utility feed B (MPPKVVCL 33 kV) | E3: 1250 A · 415 V | F3: 800 | G3: Standby | H3: MPW-33KV-0002 (sample)
A4: MP-DC-001-DC-1 | B4: MP-DC-001 | C4: DC | D4: Rectifier RECT-01 | E4: 48 V · 2400 A | F4: 115 | G4: Active
A5: TN-DC-002-AC-1 | B5: TN-DC-002 | C5: AC | D5: Utility feed A (TANGEDCO 110 kV) | E5: 2000 A · 415 V | F5: 1300 | G5: Active | H5: TNE-110KV-0001 (sample)
A6: TN-DC-002-AC-2 | B6: TN-DC-002 | C6: AC | D6: Utility feed B (TANGEDCO 110 kV) | E6: 2000 A · 415 V | F6: 1300 | G6: Standby | H6: TNE-110KV-0002 (sample)
A7: TN-DC-002-DC-1 | B7: TN-DC-002 | C7: DC | D7: Rectifier RECT-01 | E7: 48 V · 1600 A | F7: 77 | G7: Active

Sheet UPS
A1: ups_id * | B1: site_id * | C1: room_id | D1: name * | E1: vendor | F1: model | G1: serial | H1: capacity_kw * | I1: redundancy * | J1: battery_autonomy_min *
A2: MP-DC-001-UPS-1 | B2: MP-DC-001 | C2: MP-DC-001-PLANT | D2: UPS-1 | E2: Vertiv | F2: Liebert EXL S1 500 | G2: VTV-EXL-4101 | H2: 500 | I2: N+1 | J2: 15
A3: MP-DC-001-UPS-2 | B3: MP-DC-001 | C3: MP-DC-001-PLANT | D3: UPS-2 | E3: Vertiv | F3: Liebert EXL S1 500 | G3: VTV-EXL-4102 | H3: 500 | I3: N+1 | J3: 15
A4: MP-DC-001-UPS-3 | B4: MP-DC-001 | C4: MP-DC-001-PLANT | D4: UPS-3 | E4: Vertiv | F4: Liebert EXL S1 500 | G4: VTV-EXL-4103 | H4: 500 | I4: N+1 | J4: 15
A5: TN-DC-002-UPS-1 | B5: TN-DC-002 | C5: TN-DC-002-PLANT | D5: UPS-1 | E5: Schneider Electric | F5: Galaxy VX 750 | G5: SE-GVX-7701 | H5: 750 | I5: N+1 | J5: 10
A6: TN-DC-002-UPS-2 | B6: TN-DC-002 | C6: TN-DC-002-PLANT | D6: UPS-2 | E6: Schneider Electric | F6: Galaxy VX 750 | G6: SE-GVX-7702 | H6: 750 | I6: N+1 | J6: 10
A7: TN-DC-002-UPS-3 | B7: TN-DC-002 | C7: TN-DC-002-PLANT | D7: UPS-3 | E7: Schneider Electric | F7: Galaxy VX 750 | G7: SE-GVX-7703 | H7: 750 | I7: N+1 | J7: 10
A8: TN-DC-002-UPS-4 | B8: TN-DC-002 | C8: TN-DC-002-PLANT | D8: UPS-4 | E8: Schneider Electric | F8: Galaxy VX 750 | G8: SE-GVX-7704 | H8: 750 | I8: N+1 | J8: 10

Sheet Generators
A1: dg_id * | B1: site_id * | C1: name * | D1: kva * | E1: fuel_tank_litres | F1: runtime_h_full_load * | G1: last_test_date | H1: last_test_result
A2: MP-DC-001-DG-1 | B2: MP-DC-001 | C2: DG-1 | D2: 1500 | E2: 5000 | F2: 12 | G2: 46293 | H2: Pass
A3: MP-DC-001-DG-2 | B3: MP-DC-001 | C3: DG-2 | D3: 1500 | E3: 5000 | F3: 12 | G3: 46293 | H3: Pass
A4: TN-DC-002-DG-1 | B4: TN-DC-002 | C4: DG-1 | D4: 2250 | E4: 8000 | F4: 14 | G4: 46297 | H4: Pass
A5: TN-DC-002-DG-2 | B5: TN-DC-002 | C5: DG-2 | D5: 2250 | E5: 8000 | F5: 14 | G5: 46297 | H5: Pass

Sheet DC_Plant
A1: plant_id * | B1: site_id * | C1: room_id | D1: kind * | E1: name * | F1: volts | G1: ah | H1: rated_output | I1: capacity_kw | J1: autonomy_h | K1: last_test_date
A2: MP-DC-001-RECT-01 | B2: MP-DC-001 | C2: MP-DC-001-PLANT | D2: Rectifier | E2: RECT-01 | H2: 48 V · 2400 A | I2: 115 | K2: 46248
A3: MP-DC-001-BATT-01 | B3: MP-DC-001 | C3: MP-DC-001-PLANT | D3: Battery bank | E3: BATT-01 | F3: 48 | G3: 2000 | J3: 4 | K3: 46248
A4: TN-DC-002-RECT-01 | B4: TN-DC-002 | C4: TN-DC-002-PLANT | D4: Rectifier | E4: RECT-01 | H4: 48 V · 1600 A | I4: 77 | K4: 46233
A5: TN-DC-002-BATT-01 | B5: TN-DC-002 | C5: TN-DC-002-PLANT | D5: Battery bank | E5: BATT-01 | F5: 48 | G5: 1500 | J5: 3 | K5: 46233

Sheet Cooling_Units
A1: unit_id * | B1: site_id * | C1: room_id * | D1: name * | E1: type * | F1: vendor | G1: model | H1: capacity_kw * | I1: design_supply_c
A2: MP-DC-001-CRAH-01 | B2: MP-DC-001 | C2: MP-DC-001-MMR | D2: CRAH-01 | E2: CRAH | F2: Stulz | G2: CyberAir 3PRO | H2: 60 | I2: 18
A3: MP-DC-001-CRAH-11 | B3: MP-DC-001 | C3: MP-DC-001-HALLA | D3: CRAH-11 | E3: CRAH | F3: Vertiv | G3: Liebert PDX | H3: 120 | I3: 18
A4: MP-DC-001-CRAH-12 | B4: MP-DC-001 | C4: MP-DC-001-HALLA | D4: CRAH-12 | E4: CRAH | F4: Vertiv | G4: Liebert PDX | H4: 120 | I4: 18
A5: MP-DC-001-CRAH-13 | B5: MP-DC-001 | C5: MP-DC-001-HALLA | D5: CRAH-13 | E5: CRAH | F5: Vertiv | G5: Liebert PDX | H5: 120 | I5: 18
A6: MP-DC-001-CDU-01 | B6: MP-DC-001 | C6: MP-DC-001-HALLB | D6: CDU-01 | E6: CDU | F6: CoolIT | G6: CHx750 | H6: 750 | I6: 32
A7: MP-DC-001-CRAH-21 | B7: MP-DC-001 | C7: MP-DC-001-HALLB | D7: CRAH-21 | E7: CRAH | F7: Vertiv | G7: Liebert PDX | H7: 120 | I7: 20
A8: TN-DC-002-CRAH-01 | B8: TN-DC-002 | C8: TN-DC-002-MMR | D8: CRAH-01 | E8: CRAH | F8: Stulz | G8: CyberAir 3PRO | H8: 60 | I8: 18
A9: TN-DC-002-CRAH-11 | B9: TN-DC-002 | C9: TN-DC-002-NET | D9: CRAH-11 | E9: CRAH | F9: Stulz | G9: CyberAir 3PRO | H9: 120 | I9: 18
A10: TN-DC-002-CRAH-12 | B10: TN-DC-002 | C10: TN-DC-002-NET | D10: CRAH-12 | E10: CRAH | F10: Stulz | G10: CyberAir 3PRO | H10: 120 | I10: 18
A11: TN-DC-002-CDU-01 | B11: TN-DC-002 | C11: TN-DC-002-GPU1 | D11: CDU-01 | E11: CDU | F11: Vertiv | G11: Liebert XDU1350 | H11: 1350 | I11: 30
A12: TN-DC-002-CDU-02 | B12: TN-DC-002 | C12: TN-DC-002-GPU1 | D12: CDU-02 | E12: CDU | F12: Vertiv | G12: Liebert XDU1350 | H12: 1350 | I12: 30
A13: TN-DC-002-CRAH-21 | B13: TN-DC-002 | C13: TN-DC-002-GPU1 | D13: CRAH-21 | E13: CRAH | F13: Stulz | G13: CyberAir 3PRO | H13: 150 | I13: 20

Sheet CDUs
A1: cdu_id * | B1: site_id * | C1: room_id * | D1: name * | E1: capacity_kw * | F1: nominal_flow_lpm * | G1: design_supply_c | H1: racks_served (calc)
A2: MP-DC-001-CDU-01 | B2: MP-DC-001 | C2: MP-DC-001-HALLB | D2: CDU-01 | E2: 750 | F2: 1100 | G2: 32 | H2: =COUNTIF('Racks'!$O$2:$O$2000,A2)
A3: TN-DC-002-CDU-01 | B3: TN-DC-002 | C3: TN-DC-002-GPU1 | D3: CDU-01 | E3: 1350 | F3: 1900 | G3: 30 | H3: =COUNTIF('Racks'!$O$2:$O$2000,A3)
A4: TN-DC-002-CDU-02 | B4: TN-DC-002 | C4: TN-DC-002-GPU1 | D4: CDU-02 | E4: 1350 | F4: 1900 | G4: 30 | H4: =COUNTIF('Racks'!$O$2:$O$2000,A4)

Sheet Sensors
A1: sensor_id * | B1: site_id * | C1: room_id * | D1: kind * | E1: position | F1: bms_point
A2: MP-DC-001-ENV-01 | B2: MP-DC-001 | C2: MP-DC-001-MMR | D2: Temperature + humidity | E2: MMR centre | F2: BMS.MMR.TH01
A3: MP-DC-001-ENV-02 | B3: MP-DC-001 | C3: MP-DC-001-PLANT | D3: Temperature + humidity | E3: UPS row | F3: BMS.PLANT.TH02
A4: MP-DC-001-ENV-03 | B4: MP-DC-001 | C4: MP-DC-001-HALLA | D4: Temperature + humidity | E4: Cold aisle 1 | F4: BMS.HALLA.TH03
A5: MP-DC-001-ENV-04 | B5: MP-DC-001 | C5: MP-DC-001-HALLA | D5: Temperature + humidity | E5: Cold aisle 2 | F5: BMS.HALLA.TH04
A6: MP-DC-001-ENV-05 | B6: MP-DC-001 | C6: MP-DC-001-HALLB | D6: Temperature + humidity | E6: Cage row C | F6: BMS.HALLB.TH05
A7: TN-DC-002-ENV-01 | B7: TN-DC-002 | C7: TN-DC-002-MMR | D7: Temperature + humidity | E7: MMR centre | F7: BMS.MMR.TH01
A8: TN-DC-002-ENV-02 | B8: TN-DC-002 | C8: TN-DC-002-PLANT | D8: Temperature + humidity | E8: UPS row | F8: BMS.PLANT.TH02
A9: TN-DC-002-ENV-03 | B9: TN-DC-002 | C9: TN-DC-002-NET | D9: Temperature + humidity | E9: Cold aisle 1 | F9: BMS.NET.TH03
A10: TN-DC-002-ENV-04 | B10: TN-DC-002 | C10: TN-DC-002-GPU1 | D10: Temperature + humidity | E10: Row G | F10: BMS.GPU1.TH04
A11: TN-DC-002-ENV-05 | B11: TN-DC-002 | C11: TN-DC-002-GPU1 | D11: Temperature + humidity | E11: Row H | F11: BMS.GPU1.TH05
A12: MP-DC-001-ENV-06 | B12: MP-DC-001 | C12: MP-DC-001-HALLB | D12: Leak | E12: Under CDU-01 | F12: BMS.HALLB.LE06
... A15: TN-DC-002-ENV-07 | B15: TN-DC-002 | C15: TN-DC-002-PLANT | D15: Smoke | E15: Battery area | F15: BMS.PLANT.SM07

Sheet Devices
A1: device_id * | B1: site_id * | C1: hostname * | D1: role * | E1: layer * | F1: vendor * | G1: model * | H1: os_version | I1: serial | J1: mgmt_ip | K1: mac | L1: rack_id * | M1: u_position * | N1: u_size * | O1: lifecycle * | P1: owner * | Q1: tenant_customer_id | R1: monitored * | S1: collector_id | T1: wan_edge
A2: MP-DC-001-BDR-01 | B2: MP-DC-001 | C2: BDR-01 | D2: Router | E2: core | F2: Juniper | G2: MX304 | H2: Junos 23.2R2 | I2: JUNMP001007 | J2: 10.10.1.1 | K2: 3c:fd:fe:03:ef:00 | L2: MP-DC-001-MMR-R01 | M2: 1 | N2: 2 | O2: Ready | P2: operator | R2: Y | S2: COL-MP-DC-001-NET | T2: Y
A3: MP-DC-001-BDR-02 | B3: MP-DC-001 | C3: BDR-02 | D3: Router | E3: core | F3: Juniper | G3: MX304 | H3: Junos 23.2R2 | I3: JUNMP001014 | J3: 10.10.1.2 | K3: 3c:fd:fe:03:f6:01 | L3: MP-DC-001-MMR-R01 | M3: 3 | N3: 2 | O3: Ready | P3: operator | R3: Y | S3: COL-MP-DC-001-NET | T3: Y
A4: MP-DC-001-FW-01 | B4: MP-DC-001 | C4: FW-01 | D4: Firewall | E4: core | F4: Fortinet | G4: FortiGate 3700F | H4: FortiOS 7.4.4 | I4: FORMP001021 | J4: 10.10.1.11 | K4: 3c:fd:fe:03:fd:02 | L4: MP-DC-001-MMR-R01 | M4: 5 | N4: 3 | O4: Ready | P4: operator | R4: Y | S4: COL-MP-DC-001-NET | T4: N
A5: MP-DC-001-FW-02 | B5: MP-DC-001 | C5: FW-02 | D5: Firewall | E5: core | F5: Fortinet | G5: FortiGate 3700F | H5: FortiOS 7.4.4 | I5: FORMP001028 | J5: 10.10.1.12 | K5: 3c:fd:fe:04:04:03 | L5: MP-DC-001-MMR-R01 | M5: 8 | N5: 3 | O5: Ready | P5: operator | R5: Y | S5: COL-MP-DC-001-NET | T5: N
A6: MP-DC-001-MMR-SW-01 | B6: MP-DC-001 | C6: MMR-SW-01 | D6: Switch | E6: access | F6: Arista | G6: 7050SX3-48YC8 | H6: EOS 4.31.2F | I6: ARIMP001035 | J6: 10.10.1.21 | K6: 3c:fd:fe:04:0b:04 | L6: MP-DC-001-MMR-R02 | M6: 1 | N6: 1 | O6: Ready | P6: operator | R6: Y | S6: COL-MP-DC-001-NET | T6: N
A7: MP-DC-001-MMR-SW-02 | B7: MP-DC-001 | C7: MMR-SW-02 | D7: Switch | E7: access | F7: Arista | G7: 7050SX3-48YC8 | H7: EOS 4.31.2F | I7: ARIMP001042 | J7: 10.10.1.22 | K7: 3c:fd:fe:04:12:05 | L7: MP-DC-001-MMR-R02 | M7: 2 | N7: 1 | O7: Ready | P7: operator | R7: Y | S7: COL-MP-DC-001-NET | T7: N
A8: MP-DC-001-AGG-01 | B8: MP-DC-001 | C8: AGG-01 | D8: Switch | E8: spine | F8: Arista | G8: 7280R3-48YC8 | H8: EOS 4.31.2F | I8: ARIMP001049 | J8: 10.10.1.31 | K8: 3c:fd:fe:04:19:06 | L8: MP-DC-001-A01 | M8: 1 | N8: 1 | O8: Ready | P8: operator | R8: Y | S8: COL-MP-DC-001-NET | T8: N
A9: MP-DC-001-AGG-02 | B9: MP-DC-001 | C9: AGG-02 | D9: Switch | E9: spine | F9: Arista | G9: 7280R3-48YC8 | H9: EOS 4.31.2F | I9: ARIMP001056 | J9: 10.10.1.32 | K9: 3c:fd:fe:04:20:07 | L9: MP-DC-001-A01 | M9: 2 | N9: 1 | O9: Ready | P9: operator | R9: Y | S9: COL-MP-DC-001-NET | T9: N
A10: MP-DC-001-OOB-01 | B10: MP-DC-001 | C10: OOB-01 | D10: Switch | E10: access | F10: Cisco | G10: Catalyst 9300-48T | H10: IOS XE 17.9.4 | I10: CISMP001063 | J10: 10.10.1.40 | K10: 3c:fd:fe:04:27:08 | L10: MP-DC-001-A01 | M10: 3 | N10: 1 | O10: Ready | P10: operator | R10: Y | S10: COL-MP-DC-001-NET | T10: N
A11: MP-DC-001-TEN-A02 | B11: MP-DC-001 | C11: TEN-A02 | D11: Tenant gear | E11: access | F11: Tenant | G11: Tenant equipment (opaque) | L11: MP-DC-001-A02 | M11: 1 | N11: 30 | O11: Ready | P11: tenant | Q11: CUST-001 | R11: N | T11: N
A12: MP-DC-001-TEN-A03 | B12: MP-DC-001 | C12: TEN-A03 | D12: Tenant gear | E12: access | F12: Tenant | G12: Tenant equipment (opaque) | L12: MP-DC-001-A03 | M12: 1 | N12: 24 | O12: Ready | P12: tenant | Q12: CUST-001 | R12: N | T12: N
A13: MP-DC-001-TEN-A04 | B13: MP-DC-001 | C13: TEN-A04 | D13: Tenant gear | E13: access | F13: Tenant | G13: Tenant equipment (opaque) | L13: MP-DC-001-A04 | M13: 1 | N13: 34 | O13: Ready | P13: tenant | Q13: CUST-002 | R13: N | T13: N
A14: MP-DC-001-TEN-A05 | B14: MP-DC-001 | C14: TEN-A05 | D14: Tenant gear | E14: access | F14: Tenant | G14: Tenant equipment (opaque) | L14: MP-DC-001-A05 | M14: 1 | N14: 20 | O14: Ready | P14: tenant | Q14: CUST-003 | R14: N | T14: N
A15: MP-DC-001-TEN-A06 | B15: MP-DC-001 | C15: TEN-A06 | D15: Tenant gear | E15: access | F15: Tenant | G15: Tenant equipment (opaque) | L15: MP-DC-001-A06 | M15: 1 | N15: 18 | O15: Ready | P15: tenant | Q15: CUST-003 | R15: N | T15: N
A16: MP-DC-001-TEN-B01 | B16: MP-DC-001 | C16: TEN-B01 | D16: Tenant gear | E16: access | F16: Tenant | G16: Tenant equipment (opaque) | L16: MP-DC-001-B01 | M16: 1 | N16: 40 | O16: Ready | P16: tenant | Q16: CUST-004 | R16: N | T16: N
A17: MP-DC-001-TEN-B02 | B17: MP-DC-001 | C17: TEN-B02 | D17: Tenant gear | E17: access | F17: Tenant | G17: Tenant equipment (opaque) | L17: MP-DC-001-B02 | M17: 1 | N17: 40 | O17: Ready | P17: tenant | Q17: CUST-004 | R17: N | T17: N
A18: MP-DC-001-TEN-B03 | B18: MP-DC-001 | C18: TEN-B03 | D18: Tenant gear | E18: access | F18: Tenant | G18: Tenant equipment (opaque) | L18: MP-DC-001-B03 | M18: 1 | N18: 40 | O18: Ready | P18: tenant | Q18: CUST-004 | R18: N | T18: N
A19: MP-DC-001-TEN-B04 | B19: MP-DC-001 | C19: TEN-B04 | D19: Tenant gear | E19: access | F19: Tenant | G19: Tenant equipment (opaque) | L19: MP-DC-001-B04 | M19: 1 | N19: 40 | O19: Ready | P19: tenant | Q19: CUST-004 | R19: N | T19: N
A20: TN-DC-002-BDR-01 | B20: TN-DC-002 | C20: BDR-01 | D20: Router | E20: core | F20: Juniper | G20: MX304 | H20: Junos 23.2R2 | I20: JUNTN001133 | J20: 10.20.1.1 | K20: 3c:fd:fe:04:6d:12 | L20: TN-DC-002-MMR-R01 | M20: 1 | N20: 2 | O20: Ready | P20: operator | R20: Y | S20: COL-TN-DC-002-NET | T20: Y
A21: TN-DC-002-BDR-02 | B21: TN-DC-002 | C21: BDR-02 | D21: Router | E21: core | F21: Juniper | G21: MX304 | H21: Junos 23.2R2 | I21: JUNTN001140 | J21: 10.20.1.2 | K21: 3c:fd:fe:04:74:13 | L21: TN-DC-002-MMR-R01 | M21: 3 | N21: 2 | O21: Ready | P21: operator | R21: Y | S21: COL-TN-DC-002-NET | T21: Y
A22: TN-DC-002-FW-01 | B22: TN-DC-002 | C22: FW-01 | D22: Firewall | E22: core | F22: Palo Alto Networks | G22: PA-5450 | H22: PAN-OS 11.1.4 | I22: PALTN001147 | J22: 10.20.1.11 | K22: 3c:fd:fe:04:7b:14 | L22: TN-DC-002-MMR-R01 | M22: 5 | N22: 5 | O22: Ready | P22: operator | R22: Y | S22: COL-TN-DC-002-NET | T22: N
A23: TN-DC-002-FW-02 | B23: TN-DC-002 | C23: FW-02 | D23: Firewall | E23: core | F23: Palo Alto Networks | G23: PA-5450 | H23: PAN-OS 11.1.4 | I23: PALTN001154 | J23: 10.20.1.12 | K23: 3c:fd:fe:04:82:15 | L23: TN-DC-002-MMR-R01 | M23: 10 | N23: 5 | O23: Ready | P23: operator | R23: Y | S23: COL-TN-DC-002-NET | T23: N
A24: TN-DC-002-IB-SPINE-01 | B24: TN-DC-002 | C24: IB-SPINE-01 | D24: Switch | E24: spine | F24: NVIDIA | G24: Quantum-2 QM9700 | H24: MLNX-OS 3.11.2016 | I24: NVITN001161 | J24: 10.20.1.21 | K24: 3c:fd:fe:04:89:16 | L24: TN-DC-002-NET-R01 | M24: 1 | N24: 1 | O24: Ready | P24: operator | R24: Y | S24: COL-TN-DC-002-NET | T24: N
A25: TN-DC-002-IB-SPINE-02 | B25: TN-DC-002 | C25: IB-SPINE-02 | D25: Switch | E25: spine | F25: NVIDIA | G25: Quantum-2 QM9700 | H25: MLNX-OS 3.11.2016 | I25: NVITN001168 | J25: 10.20.1.22 | K25: 3c:fd:fe:04:90:17 | L25: TN-DC-002-NET-R01 | M25: 2 | N25: 1 | O25: Ready | P25: operator | R25: Y | S25: COL-TN-DC-002-NET | T25: N
A26: TN-DC-002-ETH-SPINE-01 | B26: TN-DC-002 | C26: ETH-SPINE-01 | D26: Switch | E26: spine | F26: NVIDIA | G26: Spectrum-4 SN5600 | H26: Cumulus Linux 5.9 | I26: NVITN001175 | J26: 10.20.1.31 | K26: 3c:fd:fe:04:97:18 | L26: TN-DC-002-NET-R01 | M26: 3 | N26: 2 | O26: Ready | P26: operator | R26: Y | S26: COL-TN-DC-002-NET | T26: N
A27: TN-DC-002-ETH-SPINE-02 | B27: TN-DC-002 | C27: ETH-SPINE-02 | D27: Switch | E27: spine | F27: NVIDIA | G27: Spectrum-4 SN5600 | H27: Cumulus Linux 5.9 | I27: NVITN001182 | J27: 10.20.1.32 | K27: 3c:fd:fe:04:9e:19 | L27: TN-DC-002-NET-R01 | M27: 5 | N27: 2 | O27: Ready | P27: operator | R27: Y | S27: COL-TN-DC-002-NET | T27: N
A28: TN-DC-002-IB-LEAF-01 | B28: TN-DC-002 | C28: IB-LEAF-01 | D28: Switch | E28: leaf | F28: NVIDIA | G28: Quantum-2 QM9700 | H28: MLNX-OS 3.11.2016 | I28: NVITN001189 | J28: 10.20.1.41 | K28: 3c:fd:fe:04:a5:1a | L28: TN-DC-002-NET-R02 | M28: 1 | N28: 1 | O28: Ready | P28: operator | R28: Y | S28: COL-TN-DC-002-NET | T28: N
A29: TN-DC-002-IB-LEAF-02 | B29: TN-DC-002 | C29: IB-LEAF-02 | D29: Switch | E29: leaf | F29: NVIDIA | G29: Quantum-2 QM9700 | H29: MLNX-OS 3.11.2016 | I29: NVITN001196 | J29: 10.20.1.42 | K29: 3c:fd:fe:04:ac:1b | L29: TN-DC-002-NET-R02 | M29: 2 | N29: 1 | O29: Ready | P29: operator | R29: Y | S29: COL-TN-DC-002-NET | T29: N
A30: TN-DC-002-ETH-LEAF-01 | B30: TN-DC-002 | C30: ETH-LEAF-01 | D30: Switch | E30: leaf | F30: Arista | G30: 7060DX5-64S | H30: EOS 4.32.1F | I30: ARITN001203 | J30: 10.20.1.51 | K30: 3c:fd:fe:04:b3:1c | L30: TN-DC-002-NET-R02 | M30: 3 | N30: 2 | O30: Ready | P30: operator | R30: Y | S30: COL-TN-DC-002-NET | T30: N
A31: TN-DC-002-ETH-LEAF-02 | B31: TN-DC-002 | C31: ETH-LEAF-02 | D31: Switch | E31: leaf | F31: Arista | G31: 7060DX5-64S | H31: EOS 4.32.1F | I31: ARITN001210 | J31: 10.20.1.52 | K31: 3c:fd:fe:04:ba:1d | L31: TN-DC-002-NET-R02 | M31: 5 | N31: 2 | O31: Ready | P31: operator | R31: Y | S31: COL-TN-DC-002-NET | T31: N
... A44: TN-DC-002-GPU-008 | B44: TN-DC-002 | C44: GPU-008 | D44: GPU | E44: access | F44: Supermicro | G44: SYS-821GE-TNHR (H200, liquid) | H44: Ubuntu 22.04 LTS | I44: SUPTN001301 | J44: 10.20.2.8 | K44: 3c:fd:fe:05:15:2a | L44: TN-DC-002-GPU-R04 | M44: 9 | N44: 8 | O44: Ready | P44: operator | R44: Y | S44: COL-TN-DC-002-BMC | T44: N

Sheet Modules
A1: device_id * | B1: slot * | C1: name * | D1: serial
A2: MP-DC-001-BDR-01 | B2: FPC 0 | C2: MPC10E 10x400GE | D2: JNMP000000
A3: MP-DC-001-BDR-01 | B3: PSU 0 | C3: JPSU-2200-AC | D3: JNMP000001
A4: MP-DC-001-BDR-01 | B4: PSU 1 | C4: JPSU-2200-AC | D4: JNMP000002
A5: MP-DC-001-BDR-01 | B5: RE 0 | C5: RE-X6-64G | D5: JNMP000003
A6: MP-DC-001-BDR-02 | B6: FPC 0 | C6: MPC10E 10x400GE | D6: JNMP100004
A7: MP-DC-001-BDR-02 | B7: PSU 0 | C7: JPSU-2200-AC | D7: JNMP100005
A8: MP-DC-001-BDR-02 | B8: PSU 1 | C8: JPSU-2200-AC | D8: JNMP100006
A9: MP-DC-001-BDR-02 | B9: RE 0 | C9: RE-X6-64G | D9: JNMP100007
A10: TN-DC-002-BDR-01 | B10: FPC 0 | C10: MPC10E 10x400GE | D10: JNTN000008
A11: TN-DC-002-BDR-01 | B11: PSU 0 | C11: JPSU-2200-AC | D11: JNTN000009
A12: TN-DC-002-BDR-01 | B12: PSU 1 | C12: JPSU-2200-AC | D12: JNTN000010
... A23: TN-DC-002-GPU-002 | B23: BMC | C23: AST2600 | D23: SMC0000021

Sheet Interfaces
A1: device_id * | B1: if_name * | C1: type * | D1: speed_mbps * | E1: admin_state * | F1: description | G1: optic_model
A2: MP-DC-001-BDR-01 | B2: et-0/0/0 | C2: 100GE | D2: 100000 | E2: up | F2: to FW-01 port1 | G2: QSFP28-100G-LR4
A3: MP-DC-001-FW-01 | B3: port1 | C3: 100GE | D3: 100000 | E3: up | F3: to BDR-01 et-0/0/0 | G3: QSFP28-100G-SR4
A4: MP-DC-001-FW-01 | B4: port9 | C4: 100GE | D4: 100000 | E4: up | F4: to AGG-01 Ethernet49/1 | G4: QSFP28-100G-SR4
A5: MP-DC-001-AGG-01 | B5: Ethernet49/1 | C5: 100GE | D5: 100000 | E5: up | F5: to FW-01 port9 | G5: QSFP28-100G-SR4
A6: MP-DC-001-AGG-01 | B6: Ethernet50/1 | C6: 100GE | D6: 100000 | E6: up | F6: to MMR-SW-01 Ethernet49/1
A7: MP-DC-001-MMR-SW-01 | B7: Ethernet49/1 | C7: 100GE | D7: 100000 | E7: up | F7: to AGG-01 Ethernet50/1
A8: MP-DC-001-BDR-02 | B8: et-0/0/0 | C8: 100GE | D8: 100000 | E8: up | F8: to FW-02 port1 | G8: QSFP28-100G-LR4
A9: MP-DC-001-FW-02 | B9: port1 | C9: 100GE | D9: 100000 | E9: up | F9: to BDR-02 et-0/0/0 | G9: QSFP28-100G-SR4
A10: MP-DC-001-FW-02 | B10: port9 | C10: 100GE | D10: 100000 | E10: up | F10: to AGG-02 Ethernet49/1 | G10: QSFP28-100G-SR4
A11: MP-DC-001-AGG-02 | B11: Ethernet49/1 | C11: 100GE | D11: 100000 | E11: up | F11: to FW-02 port9 | G11: QSFP28-100G-SR4
A12: MP-DC-001-AGG-02 | B12: Ethernet50/1 | C12: 100GE | D12: 100000 | E12: up | F12: to MMR-SW-02 Ethernet49/1
A13: MP-DC-001-MMR-SW-02 | B13: Ethernet49/1 | C13: 100GE | D13: 100000 | E13: up | F13: to AGG-02 Ethernet50/1
A14: MP-DC-001-BDR-01 | B14: et-0/0/1 | C14: 100GE | D14: 100000 | E14: up | F14: to BDR-02 et-0/0/1
A15: MP-DC-001-BDR-02 | B15: et-0/0/1 | C15: 100GE | D15: 100000 | E15: up | F15: to BDR-01 et-0/0/1
A16: MP-DC-001-AGG-01 | B16: Ethernet51/1 | C16: 100GE | D16: 100000 | E16: up | F16: to AGG-02 Ethernet51/1
A17: MP-DC-001-AGG-02 | B17: Ethernet51/1 | C17: 100GE | D17: 100000 | E17: up | F17: to AGG-01 Ethernet51/1
A18: MP-DC-001-OOB-01 | B18: GigabitEthernet1/0/1 | C18: 1GE | D18: 1000 | E18: up | F18: to BDR-01 mgmt0
A19: MP-DC-001-BDR-01 | B19: mgmt0 | C19: 1GE | D19: 1000 | E19: up | F19: to OOB-01 GigabitEthernet1/0/1
A20: MP-DC-001-OOB-01 | B20: GigabitEthernet1/0/2 | C20: 1GE | D20: 1000 | E20: up | F20: to BDR-02 mgmt0
A21: MP-DC-001-BDR-02 | B21: mgmt0 | C21: 1GE | D21: 1000 | E21: up | F21: to OOB-01 GigabitEthernet1/0/2
A22: MP-DC-001-OOB-01 | B22: GigabitEthernet1/0/3 | C22: 1GE | D22: 1000 | E22: up | F22: to FW-01 mgmt
A23: MP-DC-001-FW-01 | B23: mgmt | C23: 1GE | D23: 1000 | E23: up | F23: to OOB-01 GigabitEthernet1/0/3
... A33: MP-DC-001-AGG-02 | B33: mgmt0 | C33: 1GE | D33: 1000 | E33: up | F33: to OOB-01 GigabitEthernet1/0/8
A34: MP-DC-001-MMR-SW-01 | B34: Ethernet1 | C34: 10GE | D34: 10000 | E34: up | F34: XC to CUST-001 cabinet A02 | G34: SFP-10G-LR
A35: MP-DC-001-MMR-SW-02 | B35: Ethernet2 | C35: 10GE | D35: 10000 | E35: up | F35: XC to CUST-001 cabinet A03 | G35: SFP-10G-LR
A36: MP-DC-001-MMR-SW-01 | B36: Ethernet3 | C36: 10GE | D36: 10000 | E36: up | F36: XC to CUST-002 cabinet A04 | G36: SFP-10G-LR
A37: MP-DC-001-MMR-SW-02 | B37: Ethernet4 | C37: 10GE | D37: 10000 | E37: up | F37: XC to CUST-003 cabinet A05 | G37: SFP-10G-LR
A38: MP-DC-001-MMR-SW-01 | B38: Ethernet5 | C38: 10GE | D38: 10000 | E38: up | F38: XC to CUST-003 cabinet A06 | G38: SFP-10G-LR
A39: MP-DC-001-BDR-01 | B39: et-0/0/4 | C39: 100GE | D39: 100000 | E39: reserved | F39: Spare, reserved for CUST-004 backhaul
A40: MP-DC-001-BDR-01 | B40: et-0/0/5 | C40: 100GE | D40: 100000 | E40: reserved | F40: Spare, reserved for CUST-004 backhaul
A41: TN-DC-002-BDR-01 | B41: et-0/0/0 | C41: 100GE | D41: 100000 | E41: up | F41: to FW-01 ethernet1/1 | G41: QSFP28-100G-LR4
A42: TN-DC-002-FW-01 | B42: ethernet1/1 | C42: 100GE | D42: 100000 | E42: up | F42: to BDR-01 et-0/0/0 | G42: QSFP28-100G-SR4
A43: TN-DC-002-FW-01 | B43: ethernet1/3 | C43: 100GE | D43: 100000 | E43: up | F43: to ETH-SPINE-01 swp1
A44: TN-DC-002-ETH-SPINE-01 | B44: swp1 | C44: 100GE | D44: 100000 | E44: up | F44: to FW-01 ethernet1/3
A45: TN-DC-002-FW-01 | B45: ethernet1/4 | C45: 100GE | D45: 100000 | E45: up | F45: to ETH-SPINE-02 swp1
A46: TN-DC-002-ETH-SPINE-02 | B46: swp1 | C46: 100GE | D46: 100000 | E46: up | F46: to FW-01 ethernet1/4
A47: TN-DC-002-BDR-02 | B47: et-0/0/0 | C47: 100GE | D47: 100000 | E47: up | F47: to FW-02 ethernet1/1 | G47: QSFP28-100G-LR4
A48: TN-DC-002-FW-02 | B48: ethernet1/1 | C48: 100GE | D48: 100000 | E48: up | F48: to BDR-02 et-0/0/0 | G48: QSFP28-100G-SR4
A49: TN-DC-002-FW-02 | B49: ethernet1/3 | C49: 100GE | D49: 100000 | E49: up | F49: to ETH-SPINE-01 swp2
...

Sheet Links
A1: link_id * | B1: a_device_id * | C1: a_if_name * | D1: z_device_id * | E1: z_if_name * | F1: role * | G1: protocol | H1: capacity_mbps * | I1: cable_id | J1: strand | K1: a_patch_port | L1: z_patch_port | M1: carrier_circuit_id
A2: LNK-0001 | B2: MP-DC-001-BDR-01 | C2: et-0/0/0 | D2: MP-DC-001-FW-01 | E2: port1 | F2: Uplink | G2: LLDP | H2: 100000 | I2: MP-DC-001-MMR-PC-01
A3: LNK-0002 | B3: MP-DC-001-FW-01 | C3: port9 | D3: MP-DC-001-AGG-01 | E3: Ethernet49/1 | F3: Uplink | G3: LLDP | H3: 100000 | I3: MP-DC-001-TRK-HA-01 | J3: 1-2 | K3: MMR-ODF-01:1 | L3: A01-ODF:1
A4: LNK-0003 | B4: MP-DC-001-AGG-01 | C4: Ethernet50/1 | D4: MP-DC-001-MMR-SW-01 | E4: Ethernet49/1 | F4: Uplink | G4: LLDP | H4: 100000 | I4: MP-DC-001-TRK-HA-03 | J4: 5-6 | K4: A01-ODF:5 | L4: MMR-ODF-01:5
A5: LNK-0004 | B5: MP-DC-001-BDR-02 | C5: et-0/0/0 | D5: MP-DC-001-FW-02 | E5: port1 | F5: Uplink | G5: LLDP | H5: 100000 | I5: MP-DC-001-MMR-PC-02
A6: LNK-0005 | B6: MP-DC-001-FW-02 | C6: port9 | D6: MP-DC-001-AGG-02 | E6: Ethernet49/1 | F6: Uplink | G6: LLDP | H6: 100000 | I6: MP-DC-001-TRK-HA-02 | J6: 3-4 | K6: MMR-ODF-01:3 | L6: A01-ODF:3
A7: LNK-0006 | B7: MP-DC-001-AGG-02 | C7: Ethernet50/1 | D7: MP-DC-001-MMR-SW-02 | E7: Ethernet49/1 | F7: Uplink | G7: LLDP | H7: 100000 | I7: MP-DC-001-TRK-HA-04 | J7: 7-8 | K7: A01-ODF:7 | L7: MMR-ODF-01:7
A8: LNK-0007 | B8: MP-DC-001-BDR-01 | C8: et-0/0/1 | D8: MP-DC-001-BDR-02 | E8: et-0/0/1 | F8: Fabric | G8: LLDP | H8: 100000 | I8: MP-DC-001-MMR-PC-05
A9: LNK-0008 | B9: MP-DC-001-AGG-01 | C9: Ethernet51/1 | D9: MP-DC-001-AGG-02 | E9: Ethernet51/1 | F9: Fabric | G9: LLDP | H9: 100000 | I9: MP-DC-001-A01-PC-01
A10: LNK-0009 | B10: MP-DC-001-OOB-01 | C10: GigabitEthernet1/0/1 | D10: MP-DC-001-BDR-01 | E10: mgmt0 | F10: Access | G10: LLDP | H10: 1000
A11: LNK-0010 | B11: MP-DC-001-OOB-01 | C11: GigabitEthernet1/0/2 | D11: MP-DC-001-BDR-02 | E11: mgmt0 | F11: Access | G11: LLDP | H11: 1000
A12: LNK-0011 | B12: MP-DC-001-OOB-01 | C12: GigabitEthernet1/0/3 | D12: MP-DC-001-FW-01 | E12: mgmt | F12: Access | G12: LLDP | H12: 1000
A13: LNK-0012 | B13: MP-DC-001-OOB-01 | C13: GigabitEthernet1/0/4 | D13: MP-DC-001-FW-02 | E13: mgmt | F13: Access | G13: LLDP | H13: 1000
A14: LNK-0013 | B14: MP-DC-001-OOB-01 | C14: GigabitEthernet1/0/5 | D14: MP-DC-001-MMR-SW-01 | E14: mgmt0 | F14: Access | G14: LLDP | H14: 1000
A15: LNK-0014 | B15: MP-DC-001-OOB-01 | C15: GigabitEthernet1/0/6 | D15: MP-DC-001-MMR-SW-02 | E15: mgmt0 | F15: Access | G15: LLDP | H15: 1000
A16: LNK-0015 | B16: MP-DC-001-OOB-01 | C16: GigabitEthernet1/0/7 | D16: MP-DC-001-AGG-01 | E16: mgmt0 | F16: Access | G16: LLDP | H16: 1000
A17: LNK-0016 | B17: MP-DC-001-OOB-01 | C17: GigabitEthernet1/0/8 | D17: MP-DC-001-AGG-02 | E17: mgmt0 | F17: Access | G17: LLDP | H17: 1000
A18: LNK-0017 | B18: TN-DC-002-BDR-01 | C18: et-0/0/0 | D18: TN-DC-002-FW-01 | E18: ethernet1/1 | F18: Uplink | G18: LLDP | H18: 100000 | I18: TN-DC-002-MMR-PC-01
A19: LNK-0018 | B19: TN-DC-002-FW-01 | C19: ethernet1/3 | D19: TN-DC-002-ETH-SPINE-01 | E19: swp1 | F19: Uplink | G19: LLDP | H19: 100000 | I19: TN-DC-002-TRK-NET-01 | J19: 1-2 | K19: MMR-ODF-01:1 | L19: NET-ODF:1
A20: LNK-0019 | B20: TN-DC-002-FW-01 | C20: ethernet1/4 | D20: TN-DC-002-ETH-SPINE-02 | E20: swp1 | F20: Uplink | G20: LLDP | H20: 100000 | I20: TN-DC-002-TRK-NET-02 | J20: 3-4 | K20: MMR-ODF-01:3 | L20: NET-ODF:3
A21: LNK-0020 | B21: TN-DC-002-BDR-02 | C21: et-0/0/0 | D21: TN-DC-002-FW-02 | E21: ethernet1/1 | F21: Uplink | G21: LLDP | H21: 100000 | I21: TN-DC-002-MMR-PC-02
A22: LNK-0021 | B22: TN-DC-002-FW-02 | C22: ethernet1/3 | D22: TN-DC-002-ETH-SPINE-01 | E22: swp2 | F22: Uplink | G22: LLDP | H22: 100000 | I22: TN-DC-002-TRK-NET-03 | J22: 5-6 | K22: MMR-ODF-01:5 | L22: NET-ODF:5
A23: LNK-0022 | B23: TN-DC-002-FW-02 | C23: ethernet1/4 | D23: TN-DC-002-ETH-SPINE-02 | E23: swp2 | F23: Uplink | G23: LLDP | H23: 100000 | I23: TN-DC-002-TRK-NET-04 | J23: 7-8 | K23: MMR-ODF-01:7 | L23: NET-ODF:7
A24: LNK-0023 | B24: TN-DC-002-BDR-01 | C24: et-0/0/1 | D24: TN-DC-002-BDR-02 | E24: et-0/0/1 | F24: Fabric | G24: LLDP | H24: 100000 | I24: TN-DC-002-MMR-PC-05
A25: LNK-0024 | B25: TN-DC-002-ETH-SPINE-01 | C25: swp10 | D25: TN-DC-002-ETH-LEAF-01 | E25: Ethernet57/1 | F25: Fabric | G25: LLDP | H25: 400000
A26: LNK-0025 | B26: TN-DC-002-IB-SPINE-01 | C26: IB1/1 | D26: TN-DC-002-IB-LEAF-01 | E26: IB1/33 | F26: Fabric | G26: LLDP | H26: 400000
A27: LNK-0026 | B27: TN-DC-002-IB-SPINE-01 | C27: IB1/2 | D27: TN-DC-002-IB-LEAF-01 | E27: IB1/34 | F27: Fabric | G27: LLDP | H27: 400000
A28: LNK-0027 | B28: TN-DC-002-ETH-SPINE-01 | C28: swp11 | D28: TN-DC-002-ETH-LEAF-02 | E28: Ethernet57/1 | F28: Fabric | G28: LLDP | H28: 400000
A29: LNK-0028 | B29: TN-DC-002-IB-SPINE-01 | C29: IB1/3 | D29: TN-DC-002-IB-LEAF-02 | E29: IB1/33 | F29: Fabric | G29: LLDP | H29: 400000
A30: LNK-0029 | B30: TN-DC-002-IB-SPINE-01 | C30: IB1/4 | D30: TN-DC-002-IB-LEAF-02 | E30: IB1/34 | F30: Fabric | G30: LLDP | H30: 400000
A31: LNK-0030 | B31: TN-DC-002-ETH-SPINE-02 | C31: swp10 | D31: TN-DC-002-ETH-LEAF-01 | E31: Ethernet58/1 | F31: Fabric | G31: LLDP | H31: 400000
A32: LNK-0031 | B32: TN-DC-002-IB-SPINE-02 | C32: IB1/1 | D32: TN-DC-002-IB-LEAF-01 | E32: IB1/35 | F32: Fabric | G32: LLDP | H32: 400000
A33: LNK-0032 | B33: TN-DC-002-IB-SPINE-02 | C33: IB1/2 | D33: TN-DC-002-IB-LEAF-01 | E33: IB1/36 | F33: Fabric | G33: LLDP | H33: 400000
A34: LNK-0033 | B34: TN-DC-002-ETH-SPINE-02 | C34: swp11 | D34: TN-DC-002-ETH-LEAF-02 | E34: Ethernet58/1 | F34: Fabric | G34: LLDP | H34: 400000
A35: LNK-0034 | B35: TN-DC-002-IB-SPINE-02 | C35: IB1/3 | D35: TN-DC-002-IB-LEAF-02 | E35: IB1/35 | F35: Fabric | G35: LLDP | H35: 400000
A36: LNK-0035 | B36: TN-DC-002-IB-SPINE-02 | C36: IB1/4 | D36: TN-DC-002-IB-LEAF-02 | E36: IB1/36 | F36: Fabric | G36: LLDP | H36: 400000
A37: LNK-0036 | B37: TN-DC-002-GPU-001 | C37: ib0 | D37: TN-DC-002-IB-LEAF-01 | E37: IB1/1 | F37: Access | G37: LLDP | H37: 400000 | I37: TN-DC-002-GPU-IB-01-0
A38: LNK-0037 | B38: TN-DC-002-GPU-001 | C38: ib1 | D38: TN-DC-002-IB-LEAF-02 | E38: IB1/1 | F38: Access | G38: LLDP | H38: 400000 | I38: TN-DC-002-GPU-IB-01-1
A39: LNK-0038 | B39: TN-DC-002-GPU-001 | C39: ib2 | D39: TN-DC-002-IB-LEAF-01 | E39: IB1/2 | F39: Access | G39: LLDP | H39: 400000 | I39: TN-DC-002-GPU-IB-01-2
A40: LNK-0039 | B40: TN-DC-002-GPU-001 | C40: ib3 | D40: TN-DC-002-IB-LEAF-02 | E40: IB1/2 | F40: Access | G40: LLDP | H40: 400000 | I40: TN-DC-002-GPU-IB-01-3
...

Sheet GPU_Clusters
A1: cluster_id * | B1: site_id * | C1: room_id * | D1: name * | E1: scheduler * | F1: fabric * | G1: gpu_model * | H1: cooling * | I1: node_count (calc)
A2: TN-DC-002-CL-01 | B2: TN-DC-002 | C2: TN-DC-002-GPU1 | D2: Chennai H200 pod 1 | E2: Slurm | F2: InfiniBand NDR 400G, rail-optimised | G2: H200 SXM 141 GB | H2: liquid | I2: =COUNTIF('GPU_Nodes'!$B$2:$B$2000,A2)

Sheet GPU_Nodes
A1: device_id * | B1: cluster_id * | C1: gpu_model * | D1: gpu_vendor * | E1: gpu_count * | F1: server_model * | G1: cooling * | H1: driver | I1: firmware
A2: TN-DC-002-GPU-001 | B2: TN-DC-002-CL-01 | C2: H200 SXM 141 GB | D2: NVIDIA | E2: 8 | F2: Supermicro SYS-821GE-TNHR | G2: liquid | H2: 550.90.07 | I2: BMC 01.03.12
A3: TN-DC-002-GPU-002 | B3: TN-DC-002-CL-01 | C3: H200 SXM 141 GB | D3: NVIDIA | E3: 8 | F3: Supermicro SYS-821GE-TNHR | G3: liquid | H3: 550.90.07 | I3: BMC 01.03.12
A4: TN-DC-002-GPU-003 | B4: TN-DC-002-CL-01 | C4: H200 SXM 141 GB | D4: NVIDIA | E4: 8 | F4: Supermicro SYS-821GE-TNHR | G4: liquid | H4: 550.90.07 | I4: BMC 01.03.12
A5: TN-DC-002-GPU-004 | B5: TN-DC-002-CL-01 | C5: H200 SXM 141 GB | D5: NVIDIA | E5: 8 | F5: Supermicro SYS-821GE-TNHR | G5: liquid | H5: 550.90.07 | I5: BMC 01.03.12
A6: TN-DC-002-GPU-005 | B6: TN-DC-002-CL-01 | C6: H200 SXM 141 GB | D6: NVIDIA | E6: 8 | F6: Supermicro SYS-821GE-TNHR | G6: liquid | H6: 550.90.07 | I6: BMC 01.03.12
A7: TN-DC-002-GPU-006 | B7: TN-DC-002-CL-01 | C7: H200 SXM 141 GB | D7: NVIDIA | E7: 8 | F7: Supermicro SYS-821GE-TNHR | G7: liquid | H7: 550.90.07 | I7: BMC 01.03.12
A8: TN-DC-002-GPU-007 | B8: TN-DC-002-CL-01 | C8: H200 SXM 141 GB | D8: NVIDIA | E8: 8 | F8: Supermicro SYS-821GE-TNHR | G8: liquid | H8: 550.90.07 | I8: BMC 01.03.12
A9: TN-DC-002-GPU-008 | B9: TN-DC-002-CL-01 | C9: H200 SXM 141 GB | D9: NVIDIA | E9: 8 | F9: Supermicro SYS-821GE-TNHR | G9: liquid | H9: 550.90.07 | I9: BMC 01.03.12

Sheet Customers
A1: customer_id * | B1: name * | C1: segment * | D1: city * | E1: state * | F1: plan * | G1: premium * | H1: account_manager | I1: monthly_revenue (calc)
A2: CUST-001 | B2: Nimbus Analytics Pvt Ltd (sample) | C2: Technology | D2: Indore | E2: Madhya Pradesh | F2: Colo Standard 3 yr | G2: N | H2: Ritu Sharma | I2: =SUMIF('Services'!$B$2:$B$2000,A2,'Services'!$M$2:$M$2000)
A3: CUST-002 | B3: Kaveri FinServ Ltd (sample) | C3: BFSI | D3: Mumbai | E3: Maharashtra | F3: Colo Premium 5 yr | G3: Y | H3: Ritu Sharma | I3: =SUMIF('Services'!$B$2:$B$2000,A3,'Services'!$M$2:$M$2000)
A4: CUST-003 | B4: Shakti Games Studio (sample) | C4: Gaming | D4: Bengaluru | E4: Karnataka | F4: Colo Standard 2 yr | G4: N | H4: Arjun Mehta | I4: =SUMIF('Services'!$B$2:$B$2000,A4,'Services'!$M$2:$M$2000)
A5: CUST-004 | B5: Indus AI Labs (sample) | C5: AI / ML | D5: Bengaluru | E5: Karnataka | F5: AI cage + reserved cluster | G5: Y | H5: Arjun Mehta | I5: =SUMIF('Services'!$B$2:$B$2000,A5,'Services'!$M$2:$M$2000)
A6: CUST-005 | B6: Medisphere Health (sample) | C6: Healthcare | D6: Chennai | E6: Tamil Nadu | F6: On-demand GPU | G6: N | H6: Karthik Iyer | I6: =SUMIF('Services'!$B$2:$B$2000,A6,'Services'!$M$2:$M$2000)
A7: CUST-006 | B7: BharatStream Media (sample) | C7: Media | D7: Chennai | E7: Tamil Nadu | F7: CPU + storage | G7: N | H7: Karthik Iyer | I7: =SUMIF('Services'!$B$2:$B$2000,A7,'Services'!$M$2:$M$2000)

Sheet Services
A1: service_id * | B1: customer_id * | C1: type * | D1: site_id * | E1: device_id | F1: if_name | G1: rack_ids | H1: gpu_node_ids | I1: qty * | J1: unit * | K1: bandwidth_mbps | L1: sla_target_pct * | M1: monthly_revenue * | N1: critical * | O1: start_date
